Workbook

Sheet по сортам
A1: выработка кукурузы
A2: дата | B2: ПП | C2: БС | D2: ВС | E2: 1с
A3: 46235
A4: 46236
A5: 46237 | C5: 388.578
A6: 46238 | B6: 138.724 | C6: 569.036
A7: 46239 | C7: 825.108
A8: 46240 | C8: 767.654
A9: 46241 | C9: 513.486 | D9: 88.721
A10: 46242 | D10: 733.019
A11: 46243 | D11: 658.796 | E11: 224.494
A12: 46244 | D12: 626.2 | E12: 147.368
A13: 46245 | D13: 695.968
A14: 46246 | D14: 899.968
A15: 46247
A16: 46248
A17: 46249
A18: 46250
A19: 46251
A20: 46252
A21: 46253
A22: 46254
A23: 46255
A24: 46256
A25: 46257
A26: 46258
... A61: 46293
A62: Итог | B62: =SUBTOTAL(109,Таблица1[ПП]) -> 138.724 | C62: =SUBTOTAL(109,Таблица1[БС]) -> 3063.862 | D62: =SUBTOTAL(109,Таблица1[ВС]) -> 3702.672 | E62: =SUBTOTAL(109,Таблица1[1с]) -> 371.862

Sheet выработка
A1: Сорт | B1: 2024 г | C1: 2025 г | D1: 2026 г
A2: ВС | B2: 13049.448 | C2: 15920.81 | D2: =+Таблица1[[#Totals],[ВС]] -> 3702.672
A3: 1с | B3: 12629.881 | C3: 17245.885 | D3: =+Таблица1[[#Totals],[1с]] -> 371.862
A4: БС (супер) | B4: 4184.744 | C4: 9825.936 | D4: =+Таблица1[[#Totals],[БС]] -> 3063.862
A5: ПП (супер) | B5: 0 | C5: 189.323 | D5: =+Таблица1[[#Totals],[ПП]] -> 138.724
A6: Кукуруза итого | B6: =SUM(B2:B5) -> 29864.073 | C6: =SUM(C2:C5) -> 43181.954 | D6: =SUM(D2:D5) -> 7277.12
A25: Показатели | B25: =+B30 -> 2026г | C25: =+C30 -> 2025г | D25: =+D30 -> 2024г | E25: =+E30 -> 2023г
A26: max выраб.в сутки тыс.шт | B26: =MAX(B31:B850) -> 899.968 | C26: =MAX(C31:C850) -> 894.416 | D26: =MAX(D31:D850) -> 857.998 | E26: =MAX(E31:E850) -> 698.071
A27: среднедевная выраб | B27: =SUM(B31:B850)/B28 -> 727.712 | C27: =SUM(C31:C850)/C28 -> 479.79949 | D27: =SUM(D31:D850)/D28 -> 432.81265 | E27: =SUM(E31:E850)/E28 -> 377.32764
A28: колич-во раб дней | B28: =COUNTIF(B31:B185,">0") -> 10 | C28: =COUNTIF(C31:C185,">0") -> 90 | D28: =COUNTIF(D31:D185,">0") -> 69 | E28: =COUNTIF(E31:E185,">0") -> 72
A30: Выработка по дням | B30: 2026г | C30: 2025г | D30: 2024г | E30: 2023г
A31: 46204
A32: 46205
A33: 46206
A34: 46207
A35: 46208
A36: 46209
A37: 46210
A38: 46211
A39: 46212
A40: 46213
A41: 46214
A42: 46215
... A55: 46228
A56: 46229 | C56: 0 | D56: 22.238
A57: 46230 | C57: 0 | D57: 0
A58: 46231 | C58: 0 | D58: 0
A59: 46232 | C59: 0 | D59: 8.04
A60: 46233 | C60: 0 | D60: 263.238
A61: 46234 | C61: 0 | D61: 81.636
A62: 46235 | C62: 0 | D62: 307.492
A63: 46236 | C63: 0 | D63: 95.595
A64: 46237 | B64: =SUM('по сортам'!B5:E5) -> 388.578 | C64: 0 | D64: 113.595
A65: 46238 | B65: =SUM('по сортам'!B6:E6) -> 707.76 | C65: 54.44 | D65: 222.432
A66: 46239 | B66: =SUM('по сортам'!B7:E7) -> 825.108 | C66: 7.728 | D66: 383.39
A67: 46240 | B67: =SUM('по сортам'!B8:E8) -> 767.654 | C67: 186.904 | D67: 313.698
A68: 46241 | B68: =SUM('по сортам'!B9:E9) -> 602.207 | C68: 277.178 | D68: 394.995
A69: 46242 | B69: =SUM('по сортам'!B10:E10) -> 733.019 | C69: 94.683 | D69: 629.813
A70: 46243 | B70: =SUM('по сортам'!B11:E11) -> 883.29 | C70: 239.021 | D70: 421.253
A71: 46244 | B71: =SUM('по сортам'!B12:E12) -> 773.568 | C71: 324.207 | D71: 0
...

Sheet простои
A1: Дата | B1: смена | C1: ЛН-1 | D1: ЛН-2 | E1: Причины простоев
A2: 46237 | B2: день | C2: 289 | D2: 646 | E2: Настройка линии в потоке.
A3: =+A2 -> 46237 | B3: ночь | C3: 255 | D3: 304 | E3: Настройка линии в потоке. Замятие банки в закатке
A4: =+A2+1 -> 46238 | B4: день | C4: 326 | D4: 123 | E4: Настройка закатки, наполнение бункеров, подбор скорости, замятие банки в закатке
A5: =+A3+1 -> 46238 | B5: ночь | C5: 127 | D5: 254 | E5: Наполнение бункеров-настройка резок под початок, замятие банки в закатке
A6: =+A4+1 -> 46239 | B6: день | C6: 55 | D6: 227 | E6: ЛН1 Мойка, наполнение бункеров после мойки. ЛН2 Наполнение бункеров - настройка синхронизации линии.
A7: =+A5+1 -> 46239 | B7: ночь | C7: 174 | D7: 159 | E7: ЛН1 Замятие банки в закатке - 3 разаОтсутствие сырья на заводе - 35 минОрг простой на первичке - 31 минМойка, наполнение бункеров после мойки. ЛН2 Отсутствие сырья на заводе - 36 минОрг простой на первичке - 31 минЗамятие банки в закатке - 2 разаМойка, наполнение бункеров после мойки.
A8: =+A6+1 -> 46240 | B8: день | C8: 116 | D8: 140 | E8: ЛН1 Замятие банки в закатке - 0 разОтсутствие сырья на заводе - 27 минНет подачи банки с депалетайзера - 2 раза - 10 минМойка, наполнение бункеров после мойки. ЛН2 Отсутствие сырья на заводе - 27 минЗамятие банки в закатке - 4 разаНет подачи банки с депалетайзера - 2 раза - 21 минМойка, наполнение бункеров после мойки.
A9: =+A7+1 -> 46240 | B9: ночь | C9: 209 | D9: 247 | E9: ЛН1 Замятие банки в закатке - 3 разаОтсутствие сырья на заводе - 35 минОрг простой на первичке - 31 минМойка, наполнение бункеров после мойки. ЛН2 Отсутствие сырья на заводе - 36 минОрг простой на первичке - 31 минЗамятие банки в закатке - 2 разаМойка, наполнение бункеров после мойки.
A10: =+A8+1 -> 46241 | B10: день | C10: 150 | D10: 256 | E10: ЛН1 Замятие банки в закатке - 3 разаНаполнение бункеров.Мойка, наполнение бункеров после мойки. ЛН2 Замятие банки в закатке - 5 разНаполнение бункеров.Мойка, наполнение бункеров после мойки.
A11: =+A9+1 -> 46241 | B11: ночь | C11: 412 | D11: 414 | E11: ЛН1 Замятие банки в закатке - 0 разНаполнение бункеров.Переход на другой сорт, хозяйство.Мойка с применением моющего, наполнение бункеров после мойки. ЛН2 Замятие банки в закатке - 1 разНаполнение бункеров.Переход на другой сорт, хозяйство.Мойка с применением моющего, наполнение бункеров после мойки.
A12: =+A10+1 -> 46242 | B12: день | C12: 292 | D12: 263 | E12: ЛН1 Замятие банки в закатке - 0 разНаполнение бункеров, разрыв в подаче тс.Не запускается каскадная мойка. ЛН2 Замятие банки в закатке - 1 разНаполнение бункеров, разрыв в подаче тс.Не запускается каскадная мойка.
A13: =+A11+1 -> 46242 | B13: ночь | C13: 197 | D13: 223 | E13: ЛН1 Замятие банки в закатке - 2 разаНет сырья, выгрузка, наполнение бункеров - 74 минМойка - 60 минНе запускается вибростол после мойки - 15 минНастройка датчика уровня масла в закатке - 3 раза - 30 мин ЛН2 Замятие банки в закатке - 11 раз - 58 минНет сырья, выгрузка, наполнение бункеров - 105 минМойка - 60 мин
A14: =+A12+1 -> 46243 | B14: день | C14: 162 | D14: 158 | E14: ЛН1 Замятие банки в закатке 4 раза - 43 минПоломка тс на эстакаде, замена тс - 7 мин.Обрыв вала на отходном транспортере - 12 минЗасыпало транспортер на каскадную мойку - 17 минСбит барьер на загрузчике корзин - 10 минМойка - 30 минНаполнение после мойки - 7 мин ЛН2 Замятие банки в закатке - 4 раза - 43 минПоломка тс на эстакаде, замена тс - 15 мин.Обрыв вала на отходном транспортере - 10 минЗасыпало транспортер на каскадную мойку - 14 минМойка - 35 минНаполнение после мойки 10 мин
A15: =+A13+1 -> 46243 | B15: ночь | C15: 119 | D15: 127 | E15: ЛН1 Замятие банки в закатке 4 раза - 18 минМойка - 60 минНаполнение после мойки - 10 минНастройка датчика безопасности двери на наполнителе - 23 мин ЛН2 Замятие банки в закатке 3 раза - 14 минЗамена датчика безопасности двери на закаточной машине - 28 минМойка - 80 минНаполнение после мойки 4 мин
... A21: =+A19+1 -> 46246 | B21: ночь | C21: 169 | D21: 228 | E21: ЛН1 Мойка - 60 минЗамятие банки в закатке -Остановки по наполнению бункеров - выход зерна. ЛН2 Мойка - 60 минЗамятие банки в закатке -Остановки по наполнению бункеров - выход зерна.
A22: =+A20+1 -> 46247 | B22: день
A23: =+A21+1 -> 46247 | B23: ночь
A24: =+A22+1 -> 46248 | B24: день
A25: =+A23+1 -> 46248 | B25: ночь
A26: =+A24+1 -> 46249 | B26: день
A27: =+A25+1 -> 46249 | B27: ночь
A28: =+A26+1 -> 46250 | B28: день
A29: =+A27+1 -> 46250 | B29: ночь
A30: =+A28+1 -> 46251 | B30: день
A31: =+A29+1 -> 46251 | B31: ночь
A32: =+A30+1 -> 46252 | B32: день
A33: =+A31+1 -> 46252 | B33: ночь
... A73: =+A71+1 -> 46272 | B73: ночь
