Workbook
Name Срез_Контрагент: #N/A
Name Срез_Культура: #N/A
Name Срез_Культура1: #N/A
Name Срез_Орошение: #N/A
Name Срез_Орошение1: #N/A
Name Срез_Полив: #N/A

Sheet ОТЧЕТ 2026
B2: ОПЕРАТИВНАЯ ИНФОРМАЦИЯ ПО СБОРУ ГОРОШКА (СЕЗОН 2026 г.)
B19: ИЮНЬ
B20: Пн | C20: Вт | D20: Ср | E20: Чт | F20: Пт | G20: Сб | H20: Вс
B21: 1 | C21: =B21+1 -> 2 | D21: =C21+1 -> 3 | E21: =D21+1 -> 4 | F21: =E21+1 -> 5 | G21: =F21+1 -> 6 | H21: =G21+1 -> 7
B22: =H21+1 -> 8 | C22: =B22+1 -> 9 | D22: =C22+1 -> 10 | E22: =D22+1 -> 11 | F22: =E22+1 -> 12 | G22: =F22+1 -> 13 | H22: =G22+1 -> 14
B23: =H22+1 -> 15 | C23: =B23+1 -> 16 | D23: =C23+1 -> 17 | E23: =D23+1 -> 18 | F23: =E23+1 -> 19 | G23: =F23+1 -> 20 | H23: =G23+1 -> 21
B24: =H23+1 -> 22 | C24: =B24+1 -> 23 | D24: =C24+1 -> 24 | E24: =D24+1 -> 25 | F24: =E24+1 -> 26 | G24: =F24+1 -> 27 | H24: =G24+1 -> 28
B25: =H24+1 -> 29 | C25: =B25+1 -> 30
B26: ИЮЛЬ
D27: =1 -> 1 | E27: =D27+1 -> 2 | F27: =E27+1 -> 3 | G27: =F27+1 -> 4 | H27: =G27+1 -> 5
B28: =H27+1 -> 6 | C28: =B28+1 -> 7 | D28: =C28+1 -> 8 | E28: =D28+1 -> 9 | F28: =E28+1 -> 10 | G28: =F28+1 -> 11 | H28: =G28+1 -> 12
B29: =H28+1 -> 13 | C29: =B29+1 -> 14 | D29: =C29+1 -> 15 | E29: =D29+1 -> 16 | F29: =E29+1 -> 17 | G29: =F29+1 -> 18 | H29: =G29+1 -> 19
B31: День уборки - | E31: 34

Sheet Свод 2026
A1: Уборка гороха овощного в 2026 году на | C1: 46209
D3: Значения
A4: Культура | B4: Дата отчета | C4: Поле | D4: Площадь уборки, га | E4: Физический вес, кг | F4: в т.ч. Продажа, кг | G4: Зачетный вес, кг | H4: Урожайность физ.вес, т/га | I4: Урожайность зач. вес, т/га | J4: Степень зрелости, %
A5: ГРК (богара) | D5: 670.96029 | E5: 3918200 | F5: 332070 | G5: 3351407.6 | H5: 5.8396899 | I5: 4.9949418 | J5: 56.257396
A6: ГРК (полив) | D6: 350.03971 | E6: 1284550 | F6: 148150 | G6: 1125748.3 | H6: 3.6697265 | I6: 3.2160588 | J6: 57.22963
A7: Агролидер (полив) | D7: 269.1 | E7: 1397320 | F7: 399320 | G7: 1257990.1 | H7: 5.1925678 | I7: 4.6748053 | J7: 60.064815
A8: Колос (полив) | D8: 373.2 | E8: 1634840 | F8: 277580 | G8: 1468262.5 | H8: 4.3806002 | I8: 3.9342511 | J8: 57.579365
A9: Общий итог | D9: 1663.3 | E9: 8234910 | F9: 1157120 | G9: 7203408.5 | H9: 4.9509469 | I9: 4.3307933 | J9: 57.260255

Sheet Структура 2026 
A2: Структура посевных площадей
A4: Отбор: | B4: Год урожая Равно "2026 г." И Участок не используется Равно "Нет"
A6: Год урожая | D6: Площадь общая | E6: Площадь сева
A7: Подразделение
A8: Культура
A9: Поле
A10: 2026 г. | D10: 8282.66 | E10: 8282.66
A11: 2. Растениеводство (20) | D11: 5345 | E11: 5345
A12: Кукуруза на зерно | D12: 237 | E12: 237
A13: А-102/1 | D13: 5 | E13: 5
A14: А-103/1 | D14: 35 | E14: 35
A15: А-108/3 | D15: 9 | E15: 9
A16: А-109/1 | D16: 18 | E16: 18
A17: А-11 | D17: 17 | E17: 17
A18: А-110/1 | D18: 7 | E18: 7
A19: А-68/1 | D19: 77 | E19: 77
A20: А-84/1 | D20: 69 | E20: 69
A21: Подсолнечник | D21: 910 | E21: 910
... A165: Итого | D165: 8282.66 | E165: 8282.66

Sheet Подробности1
A1: Сведения о уборка - Поле: А-108/7, Культура: ГРК (полив)
A3: Культура | B3: Поле | C3: Сорт | D3: Площадь поля | E3: Площадь внесения | F3: Площадь уборки
A4: ГРК (полив) | B4: А-108/7 | C4: Патриот | D4: 102 | E4: 102 | F4: 3.1307448

Sheet Подробности2
A1: Сведения о уборка - Культура: ГРК (полив)
A3: Культура | B3: Поле | C3: Сорт | D3: Площадь поля | E3: Площадь внесения | F3: Площадь уборки
A4: ГРК (полив) | B4: А-54 | C4: Женева | D4: 55 | E4: 54 | F4: 46
A5: ГРК (полив) | B5: А-82/1 | C5: Женева | D5: 20 | E5: 8 | F5: 6
A6: ГРК (полив) | B6: А-104/1 | C6: Патриот | D6: 49 | E6: 33 | F6: 0
A7: ГРК (полив) | B7: А-108/7 | C7: Патриот | D7: 102 | E7: 102 | F7: 0
A8: ГРК (полив) | B8: А-112/2 | C8: Тристар | D8: 20 | E8: 20 | F8: 20
A9: ГРК (полив) | B9: А-54 | C9: Тристар | D9: 55 | E9: 1 | F9: 9
A10: ГРК (полив) | B10: А-54/4 | C10: Тристар | D10: 39 | E10: 39 | F10: 39
A11: ГРК (полив) | B11: А-81/1 | C11: Тристар | D11: 19 | E11: 19 | F11: 19
A12: ГРК (полив) | B12: А-82/1 | C12: Тристар | D12: 20 | E12: 12 | F12: 0
A13: ГРК (полив) | B13: А-79 | C13: Увертюра | D13: 54 | E13: 54 | F13: 33
A14: ГРК (полив) | B14: А-104/1 | C14: Фаворит | D14: 49 | E14: 16 | F14: 43.994136
A15: ГРК (полив) | B15: А-113/1 | C15: Фаворит | D15: 62 | E15: 62 | F15: 16.801585

Sheet Уборка по полям 2026
B1: Культура | C1: Поле | D1: Сорт | E1: Площадь поля | F1: Площадь внесения | G1: Площадь уборки
B2: ГРК (богара) | C2: А-104/1 | D2: Женева | E2: 11 | F2: 1.5 | G2: =SUMIFS('Реестр уборки 2026'!V:V,'Реестр уборки 2026'!W:W,Таблица13[[#This Row],[Культура]],'Реестр уборки 2026'!T:T,Таблица13[[#This Row],[Поле]],'Реестр уборки 2026'!U:U,Таблица13[[#This Row],[Сорт]]) -> 0 | L2: Площадь, га
B3: ГРК (богара) | C3: А-104/1 | D3: Патриот | E3: 11 | F3: 8 | G3: =SUMIFS('Реестр уборки 2026'!V:V,'Реестр уборки 2026'!W:W,Таблица13[[#This Row],[Культура]],'Реестр уборки 2026'!T:T,Таблица13[[#This Row],[Поле]],'Реестр уборки 2026'!U:U,Таблица13[[#This Row],[Сорт]]) -> 11 | I3: Культура | J3: Поле | K3: Сорт | L3: сев | M3: уборка | N3: остаток
B4: ГРК (богара) | C4: А-104/1 | D4: Тристар | E4: 11 | F4: 1.5 | G4: =SUMIFS('Реестр уборки 2026'!V:V,'Реестр уборки 2026'!W:W,Таблица13[[#This Row],[Культура]],'Реестр уборки 2026'!T:T,Таблица13[[#This Row],[Поле]],'Реестр уборки 2026'!U:U,Таблица13[[#This Row],[Сорт]]) -> 0 | I4: ГРК (богара) | J4: А-104/1 | L4: 11 | M4: 11 | N4: =M4-L4 -> 0
B5: ГРК (богара) | C5: А-105/1 | D5: Авола | E5: 56 | F5: 54.5 | G5: =SUMIFS('Реестр уборки 2026'!V:V,'Реестр уборки 2026'!W:W,Таблица13[[#This Row],[Культура]],'Реестр уборки 2026'!T:T,Таблица13[[#This Row],[Поле]],'Реестр уборки 2026'!U:U,Таблица13[[#This Row],[Сорт]]) -> 54.5 | J5: А-105/1 | L5: 56 | M5: 56 | N5: =M5-L5 -> 0
B6: ГРК (богара) | C6: А-105/1 | D6: Женева | E6: 56 | F6: 1.5 | G6: =SUMIFS('Реестр уборки 2026'!V:V,'Реестр уборки 2026'!W:W,Таблица13[[#This Row],[Культура]],'Реестр уборки 2026'!T:T,Таблица13[[#This Row],[Поле]],'Реестр уборки 2026'!U:U,Таблица13[[#This Row],[Сорт]]) -> 1.5 | J6: А-111/1 | L6: 14 | M6: 2 | N6: =M6-L6 -> -12 | O6: убрали на зерно
B7: ГРК (богара) | C7: А-111/1 | D7: Авола | E7: 14 | F7: 14 | G7: =SUMIFS('Реестр уборки 2026'!V:V,'Реестр уборки 2026'!W:W,Таблица13[[#This Row],[Культура]],'Реестр уборки 2026'!T:T,Таблица13[[#This Row],[Поле]],'Реестр уборки 2026'!U:U,Таблица13[[#This Row],[Сорт]]) -> 2 | J7: А-112/1 | L7: 40 | M7: 40 | N7: =M7-L7 -> 0
B8: ГРК (богара) | C8: А-112/1 | D8: Авола | E8: 40 | F8: 10 | G8: =SUMIFS('Реестр уборки 2026'!V:V,'Реестр уборки 2026'!W:W,Таблица13[[#This Row],[Культура]],'Реестр уборки 2026'!T:T,Таблица13[[#This Row],[Поле]],'Реестр уборки 2026'!U:U,Таблица13[[#This Row],[Сорт]]) -> 1 | J8: А-114 | L8: 4 | M8: 4 | N8: =M8-L8 -> 0
B9: ГРК (богара) | C9: А-112/1 | D9: Тристар | E9: 40 | F9: 30 | G9: =SUMIFS('Реестр уборки 2026'!V:V,'Реестр уборки 2026'!W:W,Таблица13[[#This Row],[Культура]],'Реестр уборки 2026'!T:T,Таблица13[[#This Row],[Поле]],'Реестр уборки 2026'!U:U,Таблица13[[#This Row],[Сорт]]) -> 39 | J9: А-115/1 | L9: 63 | M9: 63 | N9: =M9-L9 -> 0
B10: ГРК (богара) | C10: А-114 | D10: Женева | E10: 4 | F10: 4 | G10: =SUMIFS('Реестр уборки 2026'!V:V,'Реестр уборки 2026'!W:W,Таблица13[[#This Row],[Культура]],'Реестр уборки 2026'!T:T,Таблица13[[#This Row],[Поле]],'Реестр уборки 2026'!U:U,Таблица13[[#This Row],[Сорт]]) -> 4 | J10: А-116/1 | L10: 47 | M10: 32 | N10: =M10-L10 -> -15 | O10: уберем на зерно
B11: ГРК (богара) | C11: А-115/1 | D11: Тристар | E11: 63 | F11: 63 | G11: =SUMIFS('Реестр уборки 2026'!V:V,'Реестр уборки 2026'!W:W,Таблица13[[#This Row],[Культура]],'Реестр уборки 2026'!T:T,Таблица13[[#This Row],[Поле]],'Реестр уборки 2026'!U:U,Таблица13[[#This Row],[Сорт]]) -> 63 | J11: А-22/1 | L11: 36 | M11: 36 | N11: =M11-L11 -> 0
B12: ГРК (богара) | C12: А-116/1 | D12: Фаворит | E12: 47 | F12: 47 | G12: =SUMIFS('Реестр уборки 2026'!V:V,'Реестр уборки 2026'!W:W,Таблица13[[#This Row],[Культура]],'Реестр уборки 2026'!T:T,Таблица13[[#This Row],[Поле]],'Реестр уборки 2026'!U:U,Таблица13[[#This Row],[Сорт]]) -> 32 | J12: А-23 | L12: 41 | M12: 20 | N12: =M12-L12 -> -21 | O12: убрали на зерно
B13: ГРК (богара) | C13: А-22/1 | D13: Тиара | E13: 36 | F13: 5 | G13: =SUMIFS('Реестр уборки 2026'!V:V,'Реестр уборки 2026'!W:W,Таблица13[[#This Row],[Культура]],'Реестр уборки 2026'!T:T,Таблица13[[#This Row],[Поле]],'Реестр уборки 2026'!U:U,Таблица13[[#This Row],[Сорт]]) -> 5 | J13: А-24/1 | L13: 39 | M13: 39 | N13: =M13-L13 -> 0
B14: ГРК (богара) | C14: А-22/1 | D14: Увертюра | E14: 36 | F14: 31 | G14: =SUMIFS('Реестр уборки 2026'!V:V,'Реестр уборки 2026'!W:W,Таблица13[[#This Row],[Культура]],'Реестр уборки 2026'!T:T,Таблица13[[#This Row],[Поле]],'Реестр уборки 2026'!U:U,Таблица13[[#This Row],[Сорт]]) -> 31 | J14: А-3 | L14: 79 | M14: 79 | N14: =M14-L14 -> 0
B15: ГРК (богара) | C15: А-23 | D15: Увертюра | E15: 41 | F15: 20 | G15: =SUMIFS('Реестр уборки 2026'!V:V,'Реестр уборки 2026'!W:W,Таблица13[[#This Row],[Культура]],'Реестр уборки 2026'!T:T,Таблица13[[#This Row],[Поле]],'Реестр уборки 2026'!U:U,Таблица13[[#This Row],[Сорт]]) -> 20 | J15: А-38 | L15: 38 | M15: 38 | N15: =M15-L15 -> 0
B16: ГРК (богара) | C16: А-23 | D16: Фаворит | E16: 41 | F16: 21 | G16: =SUMIFS('Реестр уборки 2026'!V:V,'Реестр уборки 2026'!W:W,Таблица13[[#This Row],[Культура]],'Реестр уборки 2026'!T:T,Таблица13[[#This Row],[Поле]],'Реестр уборки 2026'!U:U,Таблица13[[#This Row],[Сорт]]) -> 0 | J16: А-4/1 | L16: 111 | M16: 111 | N16: =M16-L16 -> 0
B17: ГРК (богара) | C17: А-24/1 | D17: Фаворит | E17: 39 | F17: 39 | G17: =SUMIFS('Реестр уборки 2026'!V:V,'Реестр уборки 2026'!W:W,Таблица13[[#This Row],[Культура]],'Реестр уборки 2026'!T:T,Таблица13[[#This Row],[Поле]],'Реестр уборки 2026'!U:U,Таблица13[[#This Row],[Сорт]]) -> 39 | J17: А-5/1 | L17: 63 | M17: 26 | N17: =M17-L17 -> -37 | O17: убрали на зерно
B18: ГРК (богара) | C18: А-3 | D18: Авола | E18: 79 | F18: 79 | G18: =SUMIFS('Реестр уборки 2026'!V:V,'Реестр уборки 2026'!W:W,Таблица13[[#This Row],[Культура]],'Реестр уборки 2026'!T:T,Таблица13[[#This Row],[Поле]],'Реестр уборки 2026'!U:U,Таблица13[[#This Row],[Сорт]]) -> 79 | J18: А-76/3 | L18: 41 | M18: 41 | N18: =M18-L18 -> 0
B19: ГРК (богара) | C19: А-38 | D19: Авола | E19: 38 | F19: 38 | G19: =SUMIFS('Реестр уборки 2026'!V:V,'Реестр уборки 2026'!W:W,Таблица13[[#This Row],[Культура]],'Реестр уборки 2026'!T:T,Таблица13[[#This Row],[Поле]],'Реестр уборки 2026'!U:U,Таблица13[[#This Row],[Сорт]]) -> 38 | J19: А-76/5 | L19: 14 | M19: 14 | N19: =M19-L19 -> 0
B20: ГРК (богара) | C20: А-4/1 | D20: Тиара | E20: 111 | F20: 111 | G20: =SUMIFS('Реестр уборки 2026'!V:V,'Реестр уборки 2026'!W:W,Таблица13[[#This Row],[Культура]],'Реестр уборки 2026'!T:T,Таблица13[[#This Row],[Поле]],'Реестр уборки 2026'!U:U,Таблица13[[#This Row],[Сорт]]) -> 111 | J20: А-83/1 | L20: 24 | M20: 3 | N20: =M20-L20 -> -21 | O20: убрали на зерно
B21: ГРК (богара) | C21: А-5/1 | D21: Авола | E21: 63 | F21: 63 | G21: =SUMIFS('Реестр уборки 2026'!V:V,'Реестр уборки 2026'!W:W,Таблица13[[#This Row],[Культура]],'Реестр уборки 2026'!T:T,Таблица13[[#This Row],[Поле]],'Реестр уборки 2026'!U:U,Таблица13[[#This Row],[Сорт]]) -> 26 | J21: А-83/2 | L21: 57 | M21: 57 | N21: =M21-L21 -> 0
B22: ГРК (богара) | C22: А-76/3 | D22: Авола | E22: 41 | F22: 41 | G22: =SUMIFS('Реестр уборки 2026'!V:V,'Реестр уборки 2026'!W:W,Таблица13[[#This Row],[Культура]],'Реестр уборки 2026'!T:T,Таблица13[[#This Row],[Поле]],'Реестр уборки 2026'!U:U,Таблица13[[#This Row],[Сорт]]) -> 41 | I22: ГРК (богара) Итог | L22: 778 | M22: 672 | N22: =M22-L22 -> -106
B23: ГРК (богара) | C23: А-76/5 | D23: Авола | E23: 14 | F23: 14 | G23: =SUMIFS('Реестр уборки 2026'!V:V,'Реестр уборки 2026'!W:W,Таблица13[[#This Row],[Культура]],'Реестр уборки 2026'!T:T,Таблица13[[#This Row],[Поле]],'Реестр уборки 2026'!U:U,Таблица13[[#This Row],[Сорт]]) -> 14 | I23: ГРК (полив) | J23: А-104/1 | L23: 49 | M23: 49 | N23: =M23-L23 -> 0
B24: ГРК (богара) | C24: А-83/1 | D24: Фаворит | E24: 24 | F24: 24 | G24: =SUMIFS('Реестр уборки 2026'!V:V,'Реестр уборки 2026'!W:W,Таблица13[[#This Row],[Культура]],'Реестр уборки 2026'!T:T,Таблица13[[#This Row],[Поле]],'Реестр уборки 2026'!U:U,Таблица13[[#This Row],[Сорт]]) -> 3 | J24: А-108/7 | L24: 102 | M24: 77 | N24: =M24-L24 -> -25
B25: ГРК (богара) | C25: А-83/2 | D25: Авола | E25: 57 | F25: 52 | G25: =SUMIFS('Реестр уборки 2026'!V:V,'Реестр уборки 2026'!W:W,Таблица13[[#This Row],[Культура]],'Реестр уборки 2026'!T:T,Таблица13[[#This Row],[Поле]],'Реестр уборки 2026'!U:U,Таблица13[[#This Row],[Сорт]]) -> 52 | J25: А-112/2 | L25: 20 | M25: 20 | N25: =M25-L25 -> 0
B26: ГРК (богара) | C26: А-83/2 | D26: Фаворит | E26: 57 | F26: 5 | G26: =SUMIFS('Реестр уборки 2026'!V:V,'Реестр уборки 2026'!W:W,Таблица13[[#This Row],[Культура]],'Реестр уборки 2026'!T:T,Таблица13[[#This Row],[Поле]],'Реестр уборки 2026'!U:U,Таблица13[[#This Row],[Сорт]]) -> 5 | J26: А-113/1 | L26: 62 | M26: 62 | N26: =M26-L26 -> 0
B27: ГРК (полив) | C27: А-104/1 | D27: Патриот | E27: 49 | F27: 33 | G27: =SUMIFS('Реестр уборки 2026'!V:V,'Реестр уборки 2026'!W:W,Таблица13[[#This Row],[Культура]],'Реестр уборки 2026'!T:T,Таблица13[[#This Row],[Поле]],'Реестр уборки 2026'!U:U,Таблица13[[#This Row],[Сорт]]) -> 0 | J27: А-54 | L27: 55 | M27: 55 | N27: =M27-L27 -> 0
B28: ГРК (полив) | C28: А-104/1 | D28: Фаворит | E28: 49 | F28: 16 | G28: =SUMIFS('Реестр уборки 2026'!V:V,'Реестр уборки 2026'!W:W,Таблица13[[#This Row],[Культура]],'Реестр уборки 2026'!T:T,Таблица13[[#This Row],[Поле]],'Реестр уборки 2026'!U:U,Таблица13[[#This Row],[Сорт]]) -> 49 | J28: А-54/4 | L28: 39 | M28: 39 | N28: =M28-L28 -> 0
B29: ГРК (полив) | C29: А-108/7 | D29: Патриот | E29: 102 | F29: 102 | G29: =SUMIFS('Реестр уборки 2026'!V:V,'Реестр уборки 2026'!W:W,Таблица13[[#This Row],[Культура]],'Реестр уборки 2026'!T:T,Таблица13[[#This Row],[Поле]],'Реестр уборки 2026'!U:U,Таблица13[[#This Row],[Сорт]]) -> 77 | J29: А-79 | L29: 54 | M29: 33 | N29: =M29-L29 -> -21 | O29: оставили на зерно
B30: ГРК (полив) | C30: А-112/2 | D30: Тристар | E30: 20 | F30: 20 | G30: =SUMIFS('Реестр уборки 2026'!V:V,'Реестр уборки 2026'!W:W,Таблица13[[#This Row],[Культура]],'Реестр уборки 2026'!T:T,Таблица13[[#This Row],[Поле]],'Реестр уборки 2026'!U:U,Таблица13[[#This Row],[Сорт]]) -> 20 | J30: А-81/1 | L30: 19 | M30: 19 | N30: =M30-L30 -> 0
B31: ГРК (полив) | C31: А-113/1 | D31: Фаворит | E31: 62 | F31: 62 | G31: =SUMIFS('Реестр уборки 2026'!V:V,'Реестр уборки 2026'!W:W,Таблица13[[#This Row],[Культура]],'Реестр уборки 2026'!T:T,Таблица13[[#This Row],[Поле]],'Реестр уборки 2026'!U:U,Таблица13[[#This Row],[Сорт]]) -> 62 | J31: А-82/1 | L31: 20 | M31: 6 | N31: =M31-L31 -> -14
B32: ГРК (полив) | C32: А-54 | D32: Женева | E32: 55 | F32: 54 | G32: =SUMIFS('Реестр уборки 2026'!V:V,'Реестр уборки 2026'!W:W,Таблица13[[#This Row],[Культура]],'Реестр уборки 2026'!T:T,Таблица13[[#This Row],[Поле]],'Реестр уборки 2026'!U:U,Таблица13[[#This Row],[Сорт]]) -> 46.2 | I32: ГРК (полив) Итог | L32: 420 | M32: 360 | N32: =M32-L32 -> -60
B33: ГРК (полив) | C33: А-54 | D33: Тристар | E33: 55 | F33: 1 | G33: =SUMIFS('Реестр уборки 2026'!V:V,'Реестр уборки 2026'!W:W,Таблица13[[#This Row],[Культура]],'Реестр уборки 2026'!T:T,Таблица13[[#This Row],[Поле]],'Реестр уборки 2026'!U:U,Таблица13[[#This Row],[Сорт]]) -> 8.8 | I33: Агролидер (полив) | J33: 12 Агролидер | L33: 76.64 | M33: 76.7 | N33: =M33-L33 -> 0.06
B34: ГРК (полив) | C34: А-54/4 | D34: Тристар | E34: 39 | F34: 39 | G34: =SUMIFS('Реестр уборки 2026'!V:V,'Реестр уборки 2026'!W:W,Таблица13[[#This Row],[Культура]],'Реестр уборки 2026'!T:T,Таблица13[[#This Row],[Поле]],'Реестр уборки 2026'!U:U,Таблица13[[#This Row],[Сорт]]) -> 39 | J34: 17 Агролидер | L34: 63.51 | M34: 63.5 | N34: =M34-L34 -> -0.01
B35: ГРК (полив) | C35: А-79 | D35: Увертюра | E35: 54 | F35: 54 | G35: =SUMIFS('Реестр уборки 2026'!V:V,'Реестр уборки 2026'!W:W,Таблица13[[#This Row],[Культура]],'Реестр уборки 2026'!T:T,Таблица13[[#This Row],[Поле]],'Реестр уборки 2026'!U:U,Таблица13[[#This Row],[Сорт]]) -> 33 | J35: 18 Агролидер | L35: 128.85 | M35: 128.9 | N35: =M35-L35 -> 0.05
B36: ГРК (полив) | C36: А-81/1 | D36: Тристар | E36: 19 | F36: 19 | G36: =SUMIFS('Реестр уборки 2026'!V:V,'Реестр уборки 2026'!W:W,Таблица13[[#This Row],[Культура]],'Реестр уборки 2026'!T:T,Таблица13[[#This Row],[Поле]],'Реестр уборки 2026'!U:U,Таблица13[[#This Row],[Сорт]]) -> 19 | I36: Агролидер (полив) Итог | L36: 269 | M36: 269.1 | N36: =M36-L36 -> 0.1
B37: ГРК (полив) | C37: А-82/1 | D37: Женева | E37: 20 | F37: 8 | G37: =SUMIFS('Реестр уборки 2026'!V:V,'Реестр уборки 2026'!W:W,Таблица13[[#This Row],[Культура]],'Реестр уборки 2026'!T:T,Таблица13[[#This Row],[Поле]],'Реестр уборки 2026'!U:U,Таблица13[[#This Row],[Сорт]]) -> 6 | I37: Колос (полив) | J37: 1.6 Колос | L37: 38.6 | M37: 38.6 | N37: =M37-L37 -> 0
B38: ГРК (полив) | C38: А-82/1 | D38: Тристар | E38: 20 | F38: 12 | G38: =SUMIFS('Реестр уборки 2026'!V:V,'Реестр уборки 2026'!W:W,Таблица13[[#This Row],[Культура]],'Реестр уборки 2026'!T:T,Таблица13[[#This Row],[Поле]],'Реестр уборки 2026'!U:U,Таблица13[[#This Row],[Сорт]]) -> 0 | J38: 1.7 Колос | L38: 55 | M38: 55 | N38: =M38-L38 -> 0
B39: Агролидер (полив) | C39: 12 Агролидер | D39: Женева | E39: 76.64 | F39: 46 | G39: =SUMIFS('Реестр уборки 2026'!V:V,'Реестр уборки 2026'!W:W,Таблица13[[#This Row],[Культура]],'Реестр уборки 2026'!T:T,Таблица13[[#This Row],[Поле]],'Реестр уборки 2026'!U:U,Таблица13[[#This Row],[Сорт]]) -> 46.1 | J39: 2.2 Колос | L39: 94.1 | M39: 79.1 | N39: =M39-L39 -> -15 | O39: 15 га оставлено (вымочки)
B40: Агролидер (полив) | C40: 12 Агролидер | D40: Тристар | E40: 76.64 | F40: 30.64 | G40: =SUMIFS('Реестр уборки 2026'!V:V,'Реестр уборки 2026'!W:W,Таблица13[[#This Row],[Культура]],'Реестр уборки 2026'!T:T,Таблица13[[#This Row],[Поле]],'Реестр уборки 2026'!U:U,Таблица13[[#This Row],[Сорт]]) -> 30.6 | J40: 3.1 Колос | L40: 93.9 | M40: 42 | N40: =M40-L40 -> -51.9 | O40: 7 га оставлено (вымочки)
...

Sheet Данные 2026
K1: протянуть формулу на след день
A2: 1.1 | B2: Выборка по КА, орошению | D2: 5 | I2: 8
A3: Валовый сбор | D3: Выполнение плана по сбору | E3: ПЛАН, т | F3: ФАКТ, т | G3: Исполнение плана, % | I3: Ежедневные показатели | K3: Сбор, т | L3: Значение спелости | M3: Финометр
A4: ПЛАН, т | B4: =C59 -> 9535.8 | D4: ГРК (богара) | E4: =C55 -> 3890 | F4: =D55 -> 3918.2 | G4: =IFERROR(F4/E4, ) -> 1.0072494 | I4: 1 | J4: 46176 | K4: =IFERROR(SUMIF('Реестр уборки 2026'!Z:Z,J4,'Реестр уборки 2026'!G:G)/1000, ) -> 191.51 | L4: =IFERROR(AVERAGEIF('Реестр уборки 2026'!Z:Z,'Данные 2026'!J4,'Реестр уборки 2026'!C:C),) -> 52.285714 | M4: нет данных
A5: ФАКТ, т | B5: =D59 -> 8234.91 | D5: ГРК (полив) | E5: =C56 -> 2100 | F5: =D56 -> 1284.55 | G5: =IFERROR(F5/E5, ) -> 0.61169048 | I5: 2 | J5: =J4+1 -> 46177 | K5: =IFERROR(SUMIF('Реестр уборки 2026'!Z:Z,J5,'Реестр уборки 2026'!G:G)/1000, ) -> 117.37 | L5: =IFERROR(AVERAGEIF('Реестр уборки 2026'!Z:Z,'Данные 2026'!J5,'Реестр уборки 2026'!C:C),) -> 52 | M5: нет данных
A6: Исполнение плана, % | B6: =E59 -> 0.8635783 | D6: Агролидер (полив) | E6: =C57 -> 1345 | F6: =D57 -> 1397.32 | G6: =IFERROR(F6/E6, ) -> 1.0388996 | I6: 3 | J6: =J5+1 -> 46178 | M6: нет данных
D7: Колос (полив) | E7: =C58 -> 2200.8 | F7: =D58 -> 1634.84 | G7: =IFERROR(F7/E7, ) -> 0.74283897 | I7: 4 | J7: =J6+1 -> 46179 | K7: =IFERROR(SUMIF('Реестр уборки 2026'!Z:Z,J7,'Реестр уборки 2026'!G:G)/1000, ) -> 268.92 | L7: =IFERROR(AVERAGEIF('Реестр уборки 2026'!Z:Z,'Данные 2026'!J7,'Реестр уборки 2026'!C:C),) -> 47.826087 | M7: нет данных
A8: 1.2 | I8: 5 | J8: =J7+1 -> 46180 | K8: =IFERROR(SUMIF('Реестр уборки 2026'!Z:Z,J8,'Реестр уборки 2026'!G:G)/1000, ) -> 222.31 | L8: =IFERROR(AVERAGEIF('Реестр уборки 2026'!Z:Z,'Данные 2026'!J8,'Реестр уборки 2026'!C:C),) -> 51.2 | M8: нет данных
A9: Зачетный вес | I9: 6 | J9: =J8+1 -> 46181 | K9: =IFERROR(SUMIF('Реестр уборки 2026'!Z:Z,J9,'Реестр уборки 2026'!G:G)/1000, ) -> 246.5 | L9: =IFERROR(AVERAGEIF('Реестр уборки 2026'!Z:Z,'Данные 2026'!J9,'Реестр уборки 2026'!C:C),) -> 49.55 | M9: нет данных
A10: ПЛАН, т | I10: 7 | J10: =J9+1 -> 46182 | K10: =IFERROR(SUMIF('Реестр уборки 2026'!Z:Z,J10,'Реестр уборки 2026'!G:G)/1000, ) -> 309.81 | L10: =IFERROR(AVERAGEIF('Реестр уборки 2026'!Z:Z,'Данные 2026'!J10,'Реестр уборки 2026'!C:C),) -> 53.269231 | M10: нет данных
A11: ФАКТ, т | I11: 8 | J11: =J10+1 -> 46183 | K11: =IFERROR(SUMIF('Реестр уборки 2026'!Z:Z,J11,'Реестр уборки 2026'!G:G)/1000, ) -> 373.68 | L11: =IFERROR(AVERAGEIF('Реестр уборки 2026'!Z:Z,'Данные 2026'!J11,'Реестр уборки 2026'!C:C),) -> 55.580645 | M11: нет данных
E12: =SUM(E4:E11) -> 9535.8 | F12: =SUM(F4:F11) -> 8234.91 | G12: =IFERROR(F12/E12, ) -> 0.8635783 | I12: 9 | J12: =J11+1 -> 46184 | K12: =IFERROR(SUMIF('Реестр уборки 2026'!Z:Z,J12,'Реестр уборки 2026'!G:G)/1000, ) -> 314.53 | L12: =IFERROR(AVERAGEIF('Реестр уборки 2026'!Z:Z,'Данные 2026'!J12,'Реестр уборки 2026'!C:C),) -> 61.192308 | M12: нет данных
A13: 2 | D13: 6 | I13: 10 | J13: =J12+1 -> 46185 | K13: =IFERROR(SUMIF('Реестр уборки 2026'!Z:Z,J13,'Реестр уборки 2026'!G:G)/1000, ) -> 275.87 | L13: =IFERROR(AVERAGEIF('Реестр уборки 2026'!Z:Z,'Данные 2026'!J13,'Реестр уборки 2026'!C:C),) -> 63.083333 | M13: нет данных
A14: Площадь уборки | D14: Выполнение плана по сбору | F14: Урожайность, т/га | G14: Вал, т | I14: 11 | J14: =J13+1 -> 46186 | K14: =IFERROR(SUMIF('Реестр уборки 2026'!Z:Z,J14,'Реестр уборки 2026'!G:G)/1000, ) -> 210.12 | L14: =IFERROR(AVERAGEIF('Реестр уборки 2026'!Z:Z,'Данные 2026'!J14,'Реестр уборки 2026'!C:C),) -> 60.833333 | M14: нет данных
A15: ПЛАН, га | B15: =F59 -> 1907.16 | D15: 2019 | F15: 3.3 | G15: 6813 | I15: 12 | J15: =J14+1 -> 46187 | K15: =IFERROR(SUMIF('Реестр уборки 2026'!Z:Z,J15,'Реестр уборки 2026'!G:G)/1000, ) -> 283.77 | L15: =IFERROR(AVERAGEIF('Реестр уборки 2026'!Z:Z,'Данные 2026'!J15,'Реестр уборки 2026'!C:C),) -> 62.375 | M15: нет данных
A16: ФАКТ, га | B16: =G59 -> 1674.3 | D16: 2020 | F16: 4.6 | G16: 12761 | I16: 13 | J16: =J15+1 -> 46188 | K16: =IFERROR(SUMIF('Реестр уборки 2026'!Z:Z,J16,'Реестр уборки 2026'!G:G)/1000, ) -> 274.72 | L16: =IFERROR(AVERAGEIF('Реестр уборки 2026'!Z:Z,'Данные 2026'!J16,'Реестр уборки 2026'!C:C),) -> 61.826087 | M16: нет данных
A17: Остаток, га | B17: =B15-B16 -> 232.86 | D17: 2021 | F17: 4.2 | G17: 10161 | I17: 14 | J17: =J16+1 -> 46189 | K17: =IFERROR(SUMIF('Реестр уборки 2026'!Z:Z,J17,'Реестр уборки 2026'!G:G)/1000, ) -> 224.44 | L17: =IFERROR(AVERAGEIF('Реестр уборки 2026'!Z:Z,'Данные 2026'!J17,'Реестр уборки 2026'!C:C),) -> 61.619048 | M17: нет данных
A18: Исполнение плана, % | B18: =B16/B15 -> 0.87790222 | D18: 2022 | F18: 3 | G18: 6505 | I18: 15 | J18: =J17+1 -> 46190 | K18: =IFERROR(SUMIF('Реестр уборки 2026'!Z:Z,J18,'Реестр уборки 2026'!G:G)/1000, ) -> 260.14 | L18: =IFERROR(AVERAGEIF('Реестр уборки 2026'!Z:Z,'Данные 2026'!J18,'Реестр уборки 2026'!C:C),) -> 56.391304 | M18: нет данных
A19: Убрали на зерно | D19: 2023 | F19: 5.6 | G19: 6656 | I19: 16 | J19: =J18+1 -> 46191 | K19: =IFERROR(SUMIF('Реестр уборки 2026'!Z:Z,J19,'Реестр уборки 2026'!G:G)/1000, ) -> 276.54 | L19: =IFERROR(AVERAGEIF('Реестр уборки 2026'!Z:Z,'Данные 2026'!J19,'Реестр уборки 2026'!C:C),) -> 52.84 | M19: нет данных
A20: ОСТАВИЛИ | D20: 2024 | F20: 2.7 | G20: 4371.9 | I20: 17 | J20: =J19+1 -> 46192 | K20: =IFERROR(SUMIF('Реестр уборки 2026'!Z:Z,J20,'Реестр уборки 2026'!G:G)/1000, ) -> 48.93 | L20: =IFERROR(AVERAGEIF('Реестр уборки 2026'!Z:Z,'Данные 2026'!J20,'Реестр уборки 2026'!C:C),) -> 47.333333 | M20: нет данных
A21: 3.1 | D21: 2025 | F21: 4.7835642 | G21: 7098.14 | I21: 18 | J21: =J20+1 -> 46193 | K21: =IFERROR(SUMIF('Реестр уборки 2026'!Z:Z,J21,'Реестр уборки 2026'!G:G)/1000, ) -> 53.81 | L21: =IFERROR(AVERAGEIF('Реестр уборки 2026'!Z:Z,'Данные 2026'!J21,'Реестр уборки 2026'!C:C),) -> 51.428571 | M21: нет данных
A22: Урожайность физ. вес. | D22: 2026 | F22: =B24 -> 4.9184196 | G22: =F12 -> 8234.91 | I22: 19 | J22: =J21+1 -> 46194 | K22: =IFERROR(SUMIF('Реестр уборки 2026'!Z:Z,J22,'Реестр уборки 2026'!G:G)/1000, ) -> 305.45 | L22: =IFERROR(AVERAGEIF('Реестр уборки 2026'!Z:Z,'Данные 2026'!J22,'Реестр уборки 2026'!C:C),) -> 55.933333 | M22: нет данных
A23: ПЛАН, т/га | B23: =IFERROR(B4/B15, ) -> 5 | I23: 20 | J23: =J22+1 -> 46195 | K23: =IFERROR(SUMIF('Реестр уборки 2026'!Z:Z,J23,'Реестр уборки 2026'!G:G)/1000, ) -> 278.12 | L23: =IFERROR(AVERAGEIF('Реестр уборки 2026'!Z:Z,'Данные 2026'!J23,'Реестр уборки 2026'!C:C),) -> 58.8 | M23: нет данных
A24: ФАКТ, т/га | B24: =IFERROR(B5/B16, ) -> 4.9184196 | I24: 21 | J24: =J23+1 -> 46196 | K24: =IFERROR(SUMIF('Реестр уборки 2026'!Z:Z,J24,'Реестр уборки 2026'!G:G)/1000, ) -> 283.39 | L24: =IFERROR(AVERAGEIF('Реестр уборки 2026'!Z:Z,'Данные 2026'!J24,'Реестр уборки 2026'!C:C),) -> 59.230769 | M24: нет данных
D25: 7 | I25: 22 | J25: =J24+1 -> 46197 | K25: =IFERROR(SUMIF('Реестр уборки 2026'!Z:Z,J25,'Реестр уборки 2026'!G:G)/1000, ) -> 228.04 | L25: =IFERROR(AVERAGEIF('Реестр уборки 2026'!Z:Z,'Данные 2026'!J25,'Реестр уборки 2026'!C:C),) -> 61.217391 | M25: нет данных
A26: 3.2 | D26: Распределение сырья по финометру | F26: Вес, т | G26: Доля, % | I26: 23 | J26: =J25+1 -> 46198 | K26: =IFERROR(SUMIF('Реестр уборки 2026'!Z:Z,J26,'Реестр уборки 2026'!G:G)/1000, ) -> 399.44 | L26: =IFERROR(AVERAGEIF('Реестр уборки 2026'!Z:Z,'Данные 2026'!J26,'Реестр уборки 2026'!C:C),) -> 59.529412 | M26: нет данных
A27: Урожайность зач. вес. | C27: до 40 | D27: до 40 | F27: =SUMIF('Реестр уборки 2026'!AC:AC,Таблица111[[#This Row],[Распределение сырья по финометру]],'Реестр уборки 2026'!G:G)/1000 -> 0 | G27: =IFERROR(F27/$F$33, ) -> 0 | I27: 24 | J27: =J26+1 -> 46199 | K27: =IFERROR(SUMIF('Реестр уборки 2026'!Z:Z,J27,'Реестр уборки 2026'!G:G)/1000, ) -> 245.87 | L27: =IFERROR(AVERAGEIF('Реестр уборки 2026'!Z:Z,'Данные 2026'!J27,'Реестр уборки 2026'!C:C),) -> 64.681818 | M27: нет данных
A28: ПЛАН, т/га | B28: =IFERROR(B10/B15, 0) -> 0 | C28: 40-62 | D28: 40-52 | F28: =SUMIF('Реестр уборки 2026'!AC:AC,Таблица111[[#This Row],[Распределение сырья по финометру]],'Реестр уборки 2026'!G:G)/1000 -> 1549.04 | G28: =IFERROR(F28/$F$33, ) -> 0.18810649 | I28: 25 | J28: =J27+1 -> 46200 | K28: =IFERROR(SUMIF('Реестр уборки 2026'!Z:Z,J28,'Реестр уборки 2026'!G:G)/1000, ) -> 277.62 | L28: =IFERROR(AVERAGEIF('Реестр уборки 2026'!Z:Z,'Данные 2026'!J28,'Реестр уборки 2026'!C:C),) -> 63.263158 | M28: нет данных
A29: ФАКТ, т/га | B29: =IFERROR(B11/B16, 0) -> 0 | C29: 63-66 | D29: 53-63 | F29: =SUMIF('Реестр уборки 2026'!AC:AC,Таблица111[[#This Row],[Распределение сырья по финометру]],'Реестр уборки 2026'!G:G)/1000 -> 4786.51 | G29: =IFERROR(F29/$F$33, ) -> 0.58124618 | I29: 26 | J29: =J28+1 -> 46201 | K29: =IFERROR(SUMIF('Реестр уборки 2026'!Z:Z,J29,'Реестр уборки 2026'!G:G)/1000, ) -> 344.28 | L29: =IFERROR(AVERAGEIF('Реестр уборки 2026'!Z:Z,'Данные 2026'!J29,'Реестр уборки 2026'!C:C),) -> 59.72 | M29: нет данных
C30: 67-85 | D30: 64-66 | F30: =SUMIF('Реестр уборки 2026'!AC:AC,Таблица111[[#This Row],[Распределение сырья по финометру]],'Реестр уборки 2026'!G:G)/1000 -> 1097.02 | G30: =IFERROR(F30/$F$33, ) -> 0.13321578 | I30: 27 | J30: =J29+1 -> 46202 | K30: =IFERROR(SUMIF('Реестр уборки 2026'!Z:Z,J30,'Реестр уборки 2026'!G:G)/1000, ) -> 262.1 | L30: =IFERROR(AVERAGEIF('Реестр уборки 2026'!Z:Z,'Данные 2026'!J30,'Реестр уборки 2026'!C:C),) -> 56.25 | M30: нет данных
D31: 67-85 | F31: =SUMIF('Реестр уборки 2026'!AC:AC,Таблица111[[#This Row],[Распределение сырья по финометру]],'Реестр уборки 2026'!G:G)/1000 -> 802.34 | G31: =IFERROR(F31/$F$33, ) -> 0.097431544 | I31: 28 | J31: =J30+1 -> 46203 | K31: =IFERROR(SUMIF('Реестр уборки 2026'!Z:Z,J31,'Реестр уборки 2026'!G:G)/1000, ) -> 185.66 | L31: =IFERROR(AVERAGEIF('Реестр уборки 2026'!Z:Z,'Данные 2026'!J31,'Реестр уборки 2026'!C:C),) -> 55.157895 | M31: нет данных
A32: 4 | D32: нет данных | F32: =SUMIF('Реестр уборки 2026'!AC:AC,Таблица111[[#This Row],[Распределение сырья по финометру]],'Реестр уборки 2026'!G:G)/1000 -> 0 | G32: =IFERROR(F32/$F$33, ) -> 0 | I32: 29 | J32: =J31+1 -> 46204 | K32: =IFERROR(SUMIF('Реестр уборки 2026'!Z:Z,J32,'Реестр уборки 2026'!G:G)/1000, ) -> 254.57 | L32: =IFERROR(AVERAGEIF('Реестр уборки 2026'!Z:Z,'Данные 2026'!J32,'Реестр уборки 2026'!C:C),) -> 54.619048 | M32: нет данных
A33: Информация по сырью | F33: =SUM(F27:F32) -> 8234.91 | G33: =SUM(G27:G32) -> 1 | I33: 30 | J33: =J32+1 -> 46205 | K33: =IFERROR(SUMIF('Реестр уборки 2026'!Z:Z,J33,'Реестр уборки 2026'!G:G)/1000, ) -> 283.03 | L33: =IFERROR(AVERAGEIF('Реестр уборки 2026'!Z:Z,'Данные 2026'!J33,'Реестр уборки 2026'!C:C),) -> 54.043478 | M33: нет данных
A34: Переработка | B34: =B37-B35-B36 -> 7424.59 | I34: 31 | J34: =J33+1 -> 46206 | K34: =IFERROR(SUMIF('Реестр уборки 2026'!Z:Z,J34,'Реестр уборки 2026'!G:G)/1000, ) -> 221.76 | L34: =IFERROR(AVERAGEIF('Реестр уборки 2026'!Z:Z,'Данные 2026'!J34,'Реестр уборки 2026'!C:C),) -> 59.052632 | M34: нет данных
A35: Утилизация | B35: 0 | I35: 32 | J35: =J34+1 -> 46207 | K35: =IFERROR(SUMIF('Реестр уборки 2026'!Z:Z,J35,'Реестр уборки 2026'!G:G)/1000, ) -> 255.78 | L35: =IFERROR(AVERAGEIF('Реестр уборки 2026'!Z:Z,'Данные 2026'!J35,'Реестр уборки 2026'!C:C),) -> 60.5 | M35: нет данных
A36: Реализация | B36: =810320/1000 -> 810.32 | C36: 0 | D36: - реализовано по документам отгрузки (зач вес) | I36: 33 | J36: =J35+1 -> 46208 | K36: =IFERROR(SUMIF('Реестр уборки 2026'!Z:Z,J36,'Реестр уборки 2026'!G:G)/1000, ) -> 241.54 | L36: =IFERROR(AVERAGEIF('Реестр уборки 2026'!Z:Z,'Данные 2026'!J36,'Реестр уборки 2026'!C:C),) -> 60.75 | M36: нет данных
A37: Собственное сырье | B37: =F12 -> 8234.91 | I37: 34 | J37: =J36+1 -> 46209 | K37: =IFERROR(SUMIF('Реестр уборки 2026'!Z:Z,J37,'Реестр уборки 2026'!G:G)/1000, ) -> 215.29 | L37: =IFERROR(AVERAGEIF('Реестр уборки 2026'!Z:Z,'Данные 2026'!J37,'Реестр уборки 2026'!C:C),) -> 67.470588 | M37: нет данных
A38: Закупка | B38: 0 | I38: 35 | J38: =J37+1 -> 46210 | M38: нет данных
I39: 36 | J39: =J38+1 -> 46211 | M39: нет данных
I40: 37 | J40: =J39+1 -> 46212 | M40: нет данных
...

Sheet ОТЧЕТ 2025
B2: ОПЕРАТИВНАЯ ИНФОРМАЦИЯ ПО СБОРУ ГОРОШКА (СЕЗОН 2025 г.)
B24: МАЙ
B25: Пн | C25: Вт | D25: Ср | E25: Чт | F25: Пт | G25: Сб | H25: Вс
C26: 45804 | D26: =C26+1 -> 45805 | E26: =D26+1 -> 45806 | F26: =E26+1 -> 45807 | G26: =F26+1 -> 45808
B27: ИЮНЬ
H28: =G26+1 -> 45809
B29: =H28+1 -> 45810 | C29: =B29+1 -> 45811 | D29: =C29+1 -> 45812 | E29: =D29+1 -> 45813 | F29: =E29+1 -> 45814 | G29: =F29+1 -> 45815 | H29: =G29+1 -> 45816
B30: =H29+1 -> 45817 | C30: =B30+1 -> 45818 | D30: =C30+1 -> 45819 | E30: =D30+1 -> 45820 | F30: =E30+1 -> 45821 | G30: =F30+1 -> 45822 | H30: =G30+1 -> 45823
B31: =H30+1 -> 45824 | C31: =B31+1 -> 45825 | D31: =C31+1 -> 45826 | E31: =D31+1 -> 45827 | F31: =E31+1 -> 45828 | G31: =F31+1 -> 45829 | H31: =G31+1 -> 45830
B32: =H31+1 -> 45831 | C32: =B32+1 -> 45832 | D32: =C32+1 -> 45833 | E32: =D32+1 -> 45834 | F32: =E32+1 -> 45835 | G32: =F32+1 -> 45836 | H32: =G32+1 -> 45837
B33: =H32+1 -> 45838
B34: ИЮЛЬ
C35: =B33+1 -> 45839 | D35: =C35+1 -> 45840 | E35: =D35+1 -> 45841 | F35: =E35+1 -> 45842 | G35: =F35+1 -> 45843 | H35: =G35+1 -> 45844
B36: =H35+1 -> 45845 | C36: =B36+1 -> 45846 | D36: =C36+1 -> 45847 | E36: =D36+1 -> 45848 | F36: =E36+1 -> 45849 | G36: =F36+1 -> 45850 | H36: =G36+1 -> 45851
B38: День уборки - | E38: 45

Sheet ОТЧЕТ 2024
B2: ОПЕРАТИВНАЯ ИНФОРМАЦИЯ ПО СБОРУ ГОРОШКА (СЕЗОН 2024 г.)
B21: МАЙ
B22: Пн | C22: Вт | D22: Ср | E22: Чт | F22: Пт | G22: Сб | H22: Вс
F23: 45429 | G23: 45430 | H23: 45431
B24: =H23+1 -> 45432 | C24: =B24+1 -> 45433 | D24: =C24+1 -> 45434 | E24: =D24+1 -> 45435 | F24: =E24+1 -> 45436 | G24: =F24+1 -> 45437 | H24: =G24+1 -> 45438
B25: =H24+1 -> 45439 | C25: =B25+1 -> 45440 | D25: =C25+1 -> 45441 | E25: =D25+1 -> 45442 | F25: =E25+1 -> 45443
B26: ИЮНЬ
G27: 45444 | H27: =G27+1 -> 45445
B28: =H27+1 -> 45446 | C28: =B28+1 -> 45447 | D28: =C28+1 -> 45448 | E28: =D28+1 -> 45449 | F28: =E28+1 -> 45450 | G28: =F28+1 -> 45451 | H28: =G28+1 -> 45452
B29: =H28+1 -> 45453 | C29: =B29+1 -> 45454 | D29: =C29+1 -> 45455 | E29: =D29+1 -> 45456 | F29: =E29+1 -> 45457 | G29: =F29+1 -> 45458 | H29: =G29+1 -> 45459
B30: =H29+1 -> 45460 | C30: =B30+1 -> 45461 | D30: =C30+1 -> 45462 | E30: =D30+1 -> 45463 | F30: =E30+1 -> 45464 | G30: =F30+1 -> 45465 | H30: =G30+1 -> 45466
B31: =H30+1 -> 45467 | C31: =B31+1 -> 45468 | D31: =C31+1 -> 45469 | E31: =D31+1 -> 45470 | F31: =E31+1 -> 45471 | G31: =F31+1 -> 45472 | H31: =G31+1 -> 45473
B32: ИЮЛЬ
B33: =H31+1 -> 45474 | C33: =B33+1 -> 45475 | D33: =C33+1 -> 45476 | E33: =D33+1 -> 45477 | F33: =E33+1 -> 45478 | G33: =F33+1 -> 45479 | H33: =G33+1 -> 45480
B34: =H33+1 -> 45481 | C34: =B34+1 -> 45482 | D34: =C34+1 -> 45483 | E34: =D34+1 -> 45484 | F34: =E34+1 -> 45485 | G34: =F34+1 -> 45486 | H34: =G34+1 -> 45487
B35: =H34+1 -> 45488 | C35: =B35+1 -> 45489 | D35: =C35+1 -> 45490 | E35: =D35+1 -> 45491 | F35: =E35+1 -> 45492 | G35: =F35+1 -> 45493 | H35: =G35+1 -> 45494
B36: =H35+1 -> 45495 | C36: =B36+1 -> 45496 | D36: =C36+1 -> 45497 | E36: =D36+1 -> 45498 | F36: =E36+1 -> 45499 | G36: =F36+1 -> 45500 | H36: =G36+1 -> 45501
B37: =H36+1 -> 45502 | C37: =B37+1 -> 45503 | D37: =C37+1 -> 45504

Sheet Данные 2025
A2: 1.1 | B2: Выборка по КА, орошению | D2: 5 | I2: 8
A3: Валовый сбор | D3: Выполнение плана по сбору | E3: ПЛАН, т | F3: ФАКТ, т | G3: Исполнение плана, % | I3: Ежедневные показатели | K3: Сбор, т | L3: Значение спелости | M3: Финометр
A4: ПЛАН, т | B4: =C63 -> 6798.045 | D4: Учхоз Кубань (богара) | E4: 1157.4 | F4: =D55 -> 1320.13 | G4: =IFERROR(F4/E4, ) -> 1.1405996 | I4: 1 | J4: 45804 | K4: =SUMIF('Реестр уборки 2025'!Z:Z,J4,'Реестр уборки 2025'!G:G)/1000 -> 71.35 | L4: =IFERROR(AVERAGEIF('Реестр уборки 2025'!Z:Z,'Данные 2025'!J4,'Реестр уборки 2025'!C:C),) -> 41.333333 | M4: 40-52
A5: ФАКТ, т | B5: =D63 -> 7098.14 | D5: ГРК собственные семена (богара) | E5: 910 | F5: =D56 -> 503.65 | G5: =IFERROR(F5/E5, ) -> 0.55346154 | I5: 2 | J5: 45805 | K5: =SUMIF('Реестр уборки 2025'!Z:Z,J5,'Реестр уборки 2025'!G:G)/1000 -> 98.78 | L5: =IFERROR(AVERAGEIF('Реестр уборки 2025'!Z:Z,'Данные 2025'!J5,'Реестр уборки 2025'!C:C),) -> 44 | M5: 40-52
A6: Исполнение плана, % | B6: =E63 -> 1.0441443 | D6: ГРК демо (богара) | E6: 136.5 | F6: =D57 -> 91.8 | G6: =IFERROR(F6/E6, ) -> 0.67252747 | I6: 3 | J6: 45806 | K6: =SUMIF('Реестр уборки 2025'!Z:Z,J6,'Реестр уборки 2025'!G:G)/1000 -> 10.74 | L6: =IFERROR(AVERAGEIF('Реестр уборки 2025'!Z:Z,'Данные 2025'!J6,'Реестр уборки 2025'!C:C),) -> 42.5 | M6: 40-52
D7: ГРК (богара) | E7: 936.2 | F7: =D58 -> 769.25 | G7: =IFERROR(F7/E7, ) -> 0.82167272 | I7: 4 | J7: 45807
A8: 1.2 | D8: Братковский (полив) | E8: 765 | F8: =D59 -> 842.08 | G8: =IFERROR(F8/E8, ) -> 1.1007582 | I8: 5 | J8: 45808 | K8: =SUMIF('Реестр уборки 2025'!Z:Z,J8,'Реестр уборки 2025'!G:G)/1000 -> 55.61 | L8: =IFERROR(AVERAGEIF('Реестр уборки 2025'!Z:Z,'Данные 2025'!J8,'Реестр уборки 2025'!C:C),) -> 45.625 | M8: 40-52
A9: Зачетный вес | D9: Братковский закупка (полив) | E9: 522.325 | F9: =D60 -> 561.3 | G9: =IFERROR(F9/E9, ) -> 1.0746183 | I9: 6 | J9: 45809 | K9: =SUMIF('Реестр уборки 2025'!Z:Z,J9,'Реестр уборки 2025'!G:G)/1000 -> 206.19 | L9: =IFERROR(AVERAGEIF('Реестр уборки 2025'!Z:Z,'Данные 2025'!J9,'Реестр уборки 2025'!C:C),) -> 51.588235 | M9: 40-52
A10: ПЛАН, т | D10: Агролидер (полив) | E10: 586.5 | F10: =D61 -> 1017.73 | G10: =IFERROR(F10/E10, ) -> 1.73526 | I10: 7 | J10: 45810 | K10: =SUMIF('Реестр уборки 2025'!Z:Z,J10,'Реестр уборки 2025'!G:G)/1000 -> 198.3 | L10: =IFERROR(AVERAGEIF('Реестр уборки 2025'!Z:Z,'Данные 2025'!J10,'Реестр уборки 2025'!C:C),) -> 52.9375 | M10: 53-63
A11: ФАКТ, т | D11: Колос (полив) | E11: 1784.12 | F11: =D62 -> 1992.2 | G11: =IFERROR(F11/E11, ) -> 1.1166289 | I11: 8 | J11: 45811 | K11: =SUMIF('Реестр уборки 2025'!Z:Z,J11,'Реестр уборки 2025'!G:G)/1000 -> 285.91 | L11: =IFERROR(AVERAGEIF('Реестр уборки 2025'!Z:Z,'Данные 2025'!J11,'Реестр уборки 2025'!C:C),) -> 54.666667 | M11: 53-63
E12: =SUM(E4:E11) -> 6798.045 | F12: =SUM(F4:F11) -> 7098.14 | G12: =IFERROR(F12/E12, ) -> 1.0441443 | I12: 9 | J12: 45812 | K12: =SUMIF('Реестр уборки 2025'!Z:Z,J12,'Реестр уборки 2025'!G:G)/1000 -> 339.79 | L12: =IFERROR(AVERAGEIF('Реестр уборки 2025'!Z:Z,'Данные 2025'!J12,'Реестр уборки 2025'!C:C),) -> 57.666667 | M12: 53-63
A13: 2 | D13: 6 | I13: 10 | J13: 45813 | K13: =SUMIF('Реестр уборки 2025'!Z:Z,J13,'Реестр уборки 2025'!G:G)/1000 -> 240.45 | L13: =IFERROR(AVERAGEIF('Реестр уборки 2025'!Z:Z,'Данные 2025'!J13,'Реестр уборки 2025'!C:C),) -> 53.473684 | M13: 53-63
A14: Площадь уборки | D14: Выполнение плана по сбору | F14: Урожайность, т/га | G14: Вал, т | I14: 11 | J14: 45814 | K14: =SUMIF('Реестр уборки 2025'!Z:Z,J14,'Реестр уборки 2025'!G:G)/1000 -> 417.43 | L14: =IFERROR(AVERAGEIF('Реестр уборки 2025'!Z:Z,'Данные 2025'!J14,'Реестр уборки 2025'!C:C),) -> 57.228571 | M14: 53-63
A15: ПЛАН, га | B15: =F63 -> 1675.8 | D15: 2019 | F15: 3.3 | G15: 6813 | I15: 12 | J15: 45815 | K15: =SUMIF('Реестр уборки 2025'!Z:Z,J15,'Реестр уборки 2025'!G:G)/1000 -> 163.35 | L15: =IFERROR(AVERAGEIF('Реестр уборки 2025'!Z:Z,'Данные 2025'!J15,'Реестр уборки 2025'!C:C),) -> 60.933333 | M15: 53-63
A16: ФАКТ, га | B16: =G63 -> 1483.8601 | D16: 2020 | F16: 4.6 | G16: 12761 | I16: 13 | J16: 45816 | K16: =SUMIF('Реестр уборки 2025'!Z:Z,J16,'Реестр уборки 2025'!G:G)/1000 -> 233.26 | L16: =IFERROR(AVERAGEIF('Реестр уборки 2025'!Z:Z,'Данные 2025'!J16,'Реестр уборки 2025'!C:C),) -> 60.869565 | M16: 53-63
A17: Остаток, га | B17: =B15-B16 -> 191.93991 | D17: 2021 | F17: 4.2 | G17: 10161 | I17: 14 | J17: 45817 | K17: =SUMIF('Реестр уборки 2025'!Z:Z,J17,'Реестр уборки 2025'!G:G)/1000 -> 100.73 | L17: =IFERROR(AVERAGEIF('Реестр уборки 2025'!Z:Z,'Данные 2025'!J17,'Реестр уборки 2025'!C:C),) -> 68.1 | M17: 67-85
A18: Исполнение плана, % | B18: =B16/B15 -> 0.88546371 | D18: 2022 | F18: 3 | G18: 6505 | I18: 15 | J18: 45818 | K18: =SUMIF('Реестр уборки 2025'!Z:Z,J18,'Реестр уборки 2025'!G:G)/1000 -> 243.58 | L18: =IFERROR(AVERAGEIF('Реестр уборки 2025'!Z:Z,'Данные 2025'!J18,'Реестр уборки 2025'!C:C),) -> 62.541667 | M18: 53-63
A19: Убрали на зерно | B19: 71 | D19: 2023 | F19: 5.6 | G19: 6656 | I19: 16 | J19: 45819 | K19: =SUMIF('Реестр уборки 2025'!Z:Z,J19,'Реестр уборки 2025'!G:G)/1000 -> 127.99 | L19: =IFERROR(AVERAGEIF('Реестр уборки 2025'!Z:Z,'Данные 2025'!J19,'Реестр уборки 2025'!C:C),) -> 65.090909 | M19: 64-66
A20: ОСТАВИЛИ | B20: 120.96957 | D20: 2024 | F20: 2.7 | G20: 4371.9 | I20: 17 | J20: 45820 | K20: =SUMIF('Реестр уборки 2025'!Z:Z,J20,'Реестр уборки 2025'!G:G)/1000 -> 302.41 | L20: =IFERROR(AVERAGEIF('Реестр уборки 2025'!Z:Z,'Данные 2025'!J20,'Реестр уборки 2025'!C:C),) -> 54.217391 | M20: 53-63
A21: 3.1 | D21: 2025 | F21: =B24 -> 4.7835642 | G21: =F12 -> 7098.14 | I21: 18 | J21: 45821 | K21: =SUMIF('Реестр уборки 2025'!Z:Z,J21,'Реестр уборки 2025'!G:G)/1000 -> 251.82 | L21: =IFERROR(AVERAGEIF('Реестр уборки 2025'!Z:Z,'Данные 2025'!J21,'Реестр уборки 2025'!C:C),) -> 53.583333 | M21: 53-63
A22: Урожайность физ. вес. | I22: 19 | J22: 45822 | K22: =SUMIF('Реестр уборки 2025'!Z:Z,J22,'Реестр уборки 2025'!G:G)/1000 -> 260.19 | L22: =IFERROR(AVERAGEIF('Реестр уборки 2025'!Z:Z,'Данные 2025'!J22,'Реестр уборки 2025'!C:C),) -> 63.15 | M22: 53-63
A23: ПЛАН, т/га | B23: =IFERROR(B4/B15, ) -> 4.0565968 | I23: 20 | J23: 45823 | K23: =SUMIF('Реестр уборки 2025'!Z:Z,J23,'Реестр уборки 2025'!G:G)/1000 -> 251.63 | L23: =IFERROR(AVERAGEIF('Реестр уборки 2025'!Z:Z,'Данные 2025'!J23,'Реестр уборки 2025'!C:C),) -> 67.095238 | M23: 67-85
A24: ФАКТ, т/га | B24: =IFERROR(B5/B16, ) -> 4.7835642 | I24: 21 | J24: 45824 | K24: =SUMIF('Реестр уборки 2025'!Z:Z,J24,'Реестр уборки 2025'!G:G)/1000 -> 182.08 | L24: =IFERROR(AVERAGEIF('Реестр уборки 2025'!Z:Z,'Данные 2025'!J24,'Реестр уборки 2025'!C:C),) -> 61.375 | M24: 53-63
D25: 7 | I25: 22 | J25: 45825 | K25: =SUMIF('Реестр уборки 2025'!Z:Z,J25,'Реестр уборки 2025'!G:G)/1000 -> 231.15 | L25: =IFERROR(AVERAGEIF('Реестр уборки 2025'!Z:Z,'Данные 2025'!J25,'Реестр уборки 2025'!C:C),) -> 58.117647 | M25: 53-63
A26: 3.2 | D26: Распределение сырья по финометру | F26: Вес, т | G26: Доля, % | I26: 23 | J26: 45826 | K26: =SUMIF('Реестр уборки 2025'!Z:Z,J26,'Реестр уборки 2025'!G:G)/1000 -> 157.45 | L26: =IFERROR(AVERAGEIF('Реестр уборки 2025'!Z:Z,'Данные 2025'!J26,'Реестр уборки 2025'!C:C),) -> 55.5 | M26: 53-63
A27: Урожайность зач. вес. | C27: до 40 | D27: до 40 | F27: =SUMIF('Реестр уборки 2025'!AC:AC,Таблица1[[#This Row],[Распределение сырья по финометру]],'Реестр уборки 2025'!G:G)/1000 -> 15.6 | G27: =IFERROR(F27/$F$33, ) -> 0.0021977588 | I27: 24 | J27: 45827 | K27: =SUMIF('Реестр уборки 2025'!Z:Z,J27,'Реестр уборки 2025'!G:G)/1000 -> 304.92 | L27: =IFERROR(AVERAGEIF('Реестр уборки 2025'!Z:Z,'Данные 2025'!J27,'Реестр уборки 2025'!C:C),) -> 62.826087 | M27: 53-63
A28: ПЛАН, т/га | B28: =IFERROR(B10/B15, 0) -> 0 | C28: 40-62 | D28: 40-52 | F28: =SUMIF('Реестр уборки 2025'!AC:AC,Таблица1[[#This Row],[Распределение сырья по финометру]],'Реестр уборки 2025'!G:G)/1000 -> 1875.175 | G28: =IFERROR(F28/$F$33, ) -> 0.26417836 | I28: 25 | J28: 45828 | K28: =SUMIF('Реестр уборки 2025'!Z:Z,J28,'Реестр уборки 2025'!G:G)/1000 -> 252.94 | L28: =IFERROR(AVERAGEIF('Реестр уборки 2025'!Z:Z,'Данные 2025'!J28,'Реестр уборки 2025'!C:C),) -> 64.526316 | M28: 64-66
A29: ФАКТ, т/га | B29: =IFERROR(B11/B16, 0) -> 0 | C29: 63-66 | D29: 53-63 | F29: =SUMIF('Реестр уборки 2025'!AC:AC,Таблица1[[#This Row],[Распределение сырья по финометру]],'Реестр уборки 2025'!G:G)/1000 -> 3153.785 | G29: =IFERROR(F29/$F$33, ) -> 0.44431147 | I29: 26 | J29: 45829 | K29: =SUMIF('Реестр уборки 2025'!Z:Z,J29,'Реестр уборки 2025'!G:G)/1000 -> 123.3 | L29: =IFERROR(AVERAGEIF('Реестр уборки 2025'!Z:Z,'Данные 2025'!J29,'Реестр уборки 2025'!C:C),) -> 60 | M29: 53-63
C30: 67-85 | D30: 64-66 | F30: =SUMIF('Реестр уборки 2025'!AC:AC,Таблица1[[#This Row],[Распределение сырья по финометру]],'Реестр уборки 2025'!G:G)/1000 -> 570.75 | G30: =IFERROR(F30/$F$33, ) -> 0.080408389 | I30: 27 | J30: 45830 | K30: =SUMIF('Реестр уборки 2025'!Z:Z,J30,'Реестр уборки 2025'!G:G)/1000 -> 272.42 | L30: =IFERROR(AVERAGEIF('Реестр уборки 2025'!Z:Z,'Данные 2025'!J30,'Реестр уборки 2025'!C:C),) -> 49.4 | M30: 40-52
D31: 67-85 | F31: =SUMIF('Реестр уборки 2025'!AC:AC,Таблица1[[#This Row],[Распределение сырья по финометру]],'Реестр уборки 2025'!G:G)/1000 -> 1443.44 | G31: =IFERROR(F31/$F$33, ) -> 0.20335468 | I31: 28 | J31: 45831 | K31: =SUMIF('Реестр уборки 2025'!Z:Z,J31,'Реестр уборки 2025'!G:G)/1000 -> 109.28 | L31: =IFERROR(AVERAGEIF('Реестр уборки 2025'!Z:Z,'Данные 2025'!J31,'Реестр уборки 2025'!C:C),) -> 52.875 | M31: 53-63
A32: 4 | D32: нет данных | F32: =SUMIF('Реестр уборки 2025'!AC:AC,Таблица1[[#This Row],[Распределение сырья по финометру]],'Реестр уборки 2025'!G:G)/1000 -> 39.39 | G32: =IFERROR(F32/$F$33, ) -> 0.0055493411 | I32: 29 | J32: 45832 | K32: =SUMIF('Реестр уборки 2025'!Z:Z,J32,'Реестр уборки 2025'!G:G)/1000 -> 200.28 | L32: =IFERROR(AVERAGEIF('Реестр уборки 2025'!Z:Z,'Данные 2025'!J32,'Реестр уборки 2025'!C:C),) -> 49.375 | M32: 40-52
A33: Информация по сырью | F33: =SUM(F27:F32) -> 7098.14 | G33: =SUM(G27:G32) -> 1 | I33: 30 | J33: 45833 | K33: =SUMIF('Реестр уборки 2025'!Z:Z,J33,'Реестр уборки 2025'!G:G)/1000 -> 19.23 | L33: =IFERROR(AVERAGEIF('Реестр уборки 2025'!Z:Z,'Данные 2025'!J33,'Реестр уборки 2025'!C:C),) -> 48.5 | M33: 40-52
A34: Переработка | B34: =B37-B35-B36 -> 6329.53 | I34: 31 | J34: 45834
A35: Утилизация | B35: =(108250+8280+39390)/1000 -> 155.92 | I35: 32 | J35: 45835 | K35: =SUMIF('Реестр уборки 2025'!Z:Z,J35,'Реестр уборки 2025'!G:G)/1000 -> 17.56 | L35: =IFERROR(AVERAGEIF('Реестр уборки 2025'!Z:Z,'Данные 2025'!J35,'Реестр уборки 2025'!C:C),) -> 46 | M35: 40-52
A36: Реализация | B36: 612.69 | C36: 542.3951 | D36: - реализовано по документам отгрузки (ранее было указано в отчете) | I36: 33 | J36: 45836 | K36: =SUMIF('Реестр уборки 2025'!Z:Z,J36,'Реестр уборки 2025'!G:G)/1000 -> 43.19 | L36: =IFERROR(AVERAGEIF('Реестр уборки 2025'!Z:Z,'Данные 2025'!J36,'Реестр уборки 2025'!C:C),) -> 48 | M36: 40-52
A37: Собственное сырье | B37: =F12 -> 7098.14 | I37: 34 | J37: 45837 | K37: =SUMIF('Реестр уборки 2025'!Z:Z,J37,'Реестр уборки 2025'!G:G)/1000 -> 71.97 | L37: =IFERROR(AVERAGEIF('Реестр уборки 2025'!Z:Z,'Данные 2025'!J37,'Реестр уборки 2025'!C:C),) -> 48.444444 | M37: 40-52
A38: Закупка | B38: 0 | C38: не указана закупка Брактовского, так как она была запланирована в конвейере | I38: 35 | J38: 45838 | K38: =SUMIF('Реестр уборки 2025'!Z:Z,J38,'Реестр уборки 2025'!G:G)/1000 -> 25.63 | L38: =IFERROR(AVERAGEIF('Реестр уборки 2025'!Z:Z,'Данные 2025'!J38,'Реестр уборки 2025'!C:C),) -> 52 | M38: 40-52
I39: 36 | J39: 45839 | K39: =SUMIF('Реестр уборки 2025'!Z:Z,J39,'Реестр уборки 2025'!G:G)/1000 -> 176.53 | L39: =IFERROR(AVERAGEIF('Реестр уборки 2025'!Z:Z,'Данные 2025'!J39,'Реестр уборки 2025'!C:C),) -> 54 | M39: 53-63
I40: 37 | J40: 45840 | K40: =SUMIF('Реестр уборки 2025'!Z:Z,J40,'Реестр уборки 2025'!G:G)/1000 -> 192.78 | L40: =IFERROR(AVERAGEIF('Реестр уборки 2025'!Z:Z,'Данные 2025'!J40,'Реестр уборки 2025'!C:C),) -> 52.357143 | M40: 40-52
I41: 38 | J41: 45841 | K41: =SUMIF('Реестр уборки 2025'!Z:Z,J41,'Реестр уборки 2025'!G:G)/1000 -> 204.08 | L41: =IFERROR(AVERAGEIF('Реестр уборки 2025'!Z:Z,'Данные 2025'!J41,'Реестр уборки 2025'!C:C),) -> 55.6875 | M41: 53-63
...

Sheet СВОД по полям
A1: Контрагент | B1: Полив | C1: Номер поля | D1: Сорт | E1: Площадь сева | F1: Площадь уборки | G1: Остаток площади | H1: Закрытие, % | I1: Урожайность плановая, т/га | J1: Урожайность фактическая, т/га | K1: Валовый сбор плановый, т | L1: Валовый сбор фактический, т | M1: Выполнение плана, %
A2: ООО ГРК | B2: богара | C2: А-17 | D2: Преладо | E2: 48 | F2: #VALUE! | G2: =E2-F2 -> #VALUE! | H2: =IFERROR(F2/E2,"-") -> - | I2: =4*0.9 -> 3.6 | J2: =IFERROR(L2/F2,) -> 0 | K2: =E2*I2 -> 172.8 | L2: #VALUE! | M2: =IFERROR(L2/K2,"-") -> -

Sheet Поступление на завод 
A1: Продажа | B1: (пусто)
A2: Поступление горошка на завод по дням (без учета продажи)
D3: Значения
A4: Регистратор.Дата | B4: Культура | C4: Поле | D4: Физический вес, кг | E4: Зачетный вес, кг
A5: (пусто) | B5: ГРК (богара) | D5: 3586130 | E5: 3055975.4
B6: Агролидер (полив) | D6: 998000 | E6: 898798.1
B7: Колос (полив) | D7: 1357260 | E7: 1222677.6
B8: ГРК (полив) | C8: А-54 | D8: 273690 | E8: 237835.1
C9: А-104/1 | D9: 80320 | E9: 67167.5
C10: А-82/1 | D10: 13830 | E10: 12195.1
C11: А-54/4 | D11: 151350 | E11: 133828.2
C12: А-112/2 | D12: 133390 | E12: 117881.2
C13: А-81/1 | D13: 73080 | E13: 67505.9
C14: А-108/7 | D14: 255800 | E14: 228067.9
C15: А-113/1 | D15: 154940 | E15: 134543.8
B16: ГРК (полив) Итог | D16: 1136400 | E16: 999024.7
A17: Общий итог | D17: 7077790 | E17: 6176475.8

Sheet Поступление на завод по дням
A3: Дата | B3: Физический вес, тонны | C3: Физический вес, кг | D3: Зачетный вес, кг | E3: Дата акта входного контроля | I3: По дате акта входного контроля
A4: 45804 | B4: =C4/1000 -> 29.45 | C4: 29450 | D4: 21740.7 | E4: 45804 | I4: Дата | J4: Физический вес, тонны
A5: 45805 | B5: =C5/1000 -> 98.79 | C5: 98790 | D5: 71595.6 | E5: 45805 | I5: май | J5: 227.18
A6: 45806 | B6: =C6/1000 -> 52.63 | C6: 52630 | D6: 37492 | E6: 45806 | I6: 27.май | J6: 29.45
A7: 45807 | B7: =C7/1000 -> 46.31 | C7: 46310 | D7: 33701.5 | E7: 45808 | I7: 28.май | J7: 98.79
A8: 45808 | I8: 29.май | J8: 52.63
A9: 45809 | B9: =C9/1000 -> 163.7 | C9: 163700 | D9: 124140.6 | E9: 45809 | I9: 30.май | J9: 46.31
A10: 45810 | B10: =C10/1000 -> 181.62 | C10: 181620 | D10: 141581.7 | E10: 45810 | I10: 31.май
A11: 45811 | B11: =C11/1000 -> 137.38 | C11: 137380 | D11: 111232.3 | E11: 45811 | I11: июн | J11: 5031.04
A12: 45812 | B12: =C12/1000 -> 218.34 | C12: 218340 | D12: 186899.6 | E12: 45812 | I12: 01.июн | J12: 163.7
A13: 45813 | B13: =C13/1000 -> 257.7 | C13: 257700 | D13: 215785.7 | E13: 45813 | I13: 02.июн | J13: 181.62
A14: 45814 | B14: =C14/1000 -> 187.54 | C14: 187540 | D14: 157412.6 | E14: 45814 | I14: 03.июн | J14: 137.38
A15: 45815 | B15: =C15/1000 -> 222.75 | C15: 222750 | D15: 189231 | E15: 45815 | I15: 04.июн | J15: 218.34
A16: 45816 | B16: =C16/1000 -> 244.84 | C16: 244840 | D16: 214198.4 | E16: 45816 | I16: 05.июн | J16: 257.7
A17: 45817 | B17: =C17/1000 -> 152.51 | C17: 152510 | D17: 127138.9 | E17: 45817 | I17: 06.июн | J17: 187.54
A18: 45818 | B18: =C18/1000 -> 185.62 | C18: 185620 | D18: 159943.4 | E18: 45818 | I18: 07.июн | J18: 222.75
A19: 45819 | B19: =C19/1000 -> 159.63 | C19: 159630 | D19: 146763.8 | E19: 45819 | I19: 08.июн | J19: 244.84
A20: 45820 | B20: =C20/1000 -> 269.58 | C20: 269580 | D20: 233118.8 | E20: 45820 | I20: 09.июн | J20: 152.51
A21: 45821 | B21: =C21/1000 -> 214.02 | C21: 214020 | D21: 182865.4 | E21: 45821 | I21: 10.июн | J21: 185.62
A22: 45822 | B22: =C22/1000 -> 288.24 | C22: 288240 | D22: 252886.4 | E22: 45822 | I22: 11.июн | J22: 159.63
... A33: 45833 | B33: =C33/1000 -> 125.43 | C33: 125430 | D33: 104544.2 | E33: 45833 | I33: 22.июн | J33: 204.71
A34: 45834 | I34: 23.июн | J34: 228.57
A35: 45835 | I35: 24.июн | J35: 94.08
A36: 45836 | B36: =C36/1000 -> 60.75 | C36: 60750 | D36: 51333.9 | E36: 45836 | I36: 25.июн | J36: 125.43
A37: 45837 | B37: =C37/1000 -> 69.23 | C37: 69230 | D37: 60600.6 | E37: 45837 | I37: 26.июн
A38: 45838 | B38: =C38/1000 -> 28.37 | C38: 28370 | D38: 24692.3 | E38: 45838 | I38: 27.июн
A39: 45839 | B39: =C39/1000 -> 69.19 | C39: 69190 | D39: 60335.2 | E39: 45839 | I39: 28.июн | J39: 60.75
A40: 45840 | B40: =C40/1000 -> 218.92 | C40: 218920 | D40: 187414.8 | E40: 45840 | I40: 29.июн | J40: 69.23
A41: 45841 | B41: =C41/1000 -> 192.37 | C41: 192370 | D41: 161740.5 | E41: 45841 | I41: 30.июн | J41: 28.37
A42: 45842 | B42: =C42/1000 -> 213.73 | C42: 213730 | D42: 190148.5 | E42: 45842 | I42: июл | J42: 1227.23
A43: 45843 | B43: =C43/1000 -> 84.68 | C43: 84680 | D43: 73460.3 | E43: 45843 | I43: 01.июл | J43: 69.19
A44: 45844 | B44: =C44/1000 -> 226.12 | C44: 226120 | D44: 203439.1 | E44: 45844 | I44: 02.июл | J44: 218.92
A45: 45845 | I45: 03.июл | J45: 192.37
A46: 45846 | B46: =C46/1000 -> 40.51 | C46: 40510 | D46: 36604.8 | E46: 45846 | I46: 04.июл | J46: 213.73
A47: 45847 | B47: =C47/1000 -> 143.24 | C47: 143240 | D47: 125850.3 | E47: 45847 | I47: 05.июл | J47: 84.68
A48: 45848 | B48: =C48/1000 -> 38.47 | C48: 38470 | D48: 31337.5 | E48: 45848 | I48: 06.июл | J48: 226.12
I49: 07.июл
I50: 08.июл | J50: 40.51
I51: 09.июл | J51: 143.24
I52: 10.июл | J52: 38.47
...

Sheet по дням
A1: Продажа | B1: (пусто)
A3: Вес нетто, т | B3: Характеристика
A4: Регистратор.Дата | B4: Первый | C4: Высший | D4: Второй | E4: Общий итог
A5: (пусто) | B5: 1434.53 | C5: 5468.02 | D5: 175.24 | E5: 7077.79
A6: Общий итог | B6: 1434.53 | C6: 5468.02 | D6: 175.24 | E6: 7077.79

Sheet Сев 2026
B1: Поле | C1: Культура | D1: Авола | E1: Площадь поля | F1: Площадь внесения
B2: А-104/1 | C2: Горошек овощной (богара) | E2: 11 | F2: 11
B3: Семена гороха ( п.е.) | C3: Женева 100 т.с. | D3: Женева | E3: 11 | F3: 1.5
B4: Семена гороха овощного протравленные | C4: Тристар 100 тыс.с (лот D0021 15 T25-3033ST) | D4: Тристар | E4: 11 | F4: 1.5
B5: Семена гороха овощного протравленные (кг) | C5: Патриот ЭС | D5: Патриот | E5: 11 | F5: 8
B6: А-105/1 | C6: Горошек овощной (богара) | E6: 56 | F6: 56
B7: Семена гороха ( п.е.) | C7: Женева 100 т.с. | D7: Женева | E7: 56 | F7: 1.5
B8: Семена гороха овощного протравленные | C8: Авола 100 тыс.с (лот D0021 15 K25-6011ST) | D8: Авола | E8: 56 | F8: 24
B9: Семена гороха овощного протравленные | C9: Авола 100 тыс.с (лот D0021 15 K25-6012ST) | D9: Авола | E9: 56 | F9: 30.5
B10: А-111/1 | C10: Горошек овощной (богара) | E10: 14 | F10: 14
B11: Семена гороха овощного протравленные | C11: Авола 100 тыс.с (лот Kl1038104) | D11: Авола | E11: 14 | F11: 14
B12: А-112/1 | C12: Горошек овощной (богара) | E12: 40 | F12: 40
B13: Семена гороха овощного протравленные | C13: Авола 100 тыс.с (лот Kl1038104) | D13: Авола | E13: 40 | F13: 10
B14: Семена гороха овощного протравленные | C14: Тристар 100 тыс.с (лот ES1038103) | D14: Тристар | E14: 40 | F14: 30
B15: А-114 | C15: Горошек овощной (богара) | E15: 4 | F15: 4
B16: Семена гороха ( п.е.) | C16: Женева 100 т.с. | D16: Женева | E16: 4 | F16: 4
B17: А-115/1 | C17: Горошек овощной (богара) | E17: 63 | F17: 63
B18: Семена гороха овощного протравленные | C18: Тристар 100 тыс.с (лот D0021 15 T25-3033ST) | D18: Тристар | E18: 63 | F18: 21
B19: Семена гороха овощного протравленные | C19: Тристар 100 тыс.с (лот ES1038103) | D19: Тристар | E19: 63 | F19: 42
B20: А-116/1 | C20: Горошек овощной (богара) | E20: 47 | F20: 94
B21: Семена гороха овощного протравленные | C21: Фаворит 100 т.с.(партия Н-Х/4402) | D21: Фаворит | E21: 47 | F21: 47
B22: Семена гороха овощного протравленные | C22: Фаворит 100 т.с.(партия Н-Х/5126) | D22: Фаворит | E22: 47 | F22: 36
B23: Семена гороха овощного протравленные | C23: Фаворит 100 т.с.(партия Н-Х/5128) | D23: Фаворит | E23: 47 | F23: 11
B24: А-22/1 | C24: Горошек овощной (богара) | E24: 36 | F24: 36
B25: Семена гороха ( п.е.) | C25: Увертюра 100 000 | D25: Увертюра | E25: 36 | F25: 31
B26: Семена гороха овощного протравленные | C26: Тиара 100 т.с.(партия Н-Х/5120) | D26: Тиара | E26: 36 | F26: 5
B27: А-23 | C27: Горошек овощной (богара) | E27: 41 | F27: 41
B28: Семена гороха ( п.е.) | C28: Увертюра 100 000 | D28: Увертюра | E28: 41 | F28: 20
B29: Семена гороха овощного протравленные | C29: Фаворит 100 т.с.(партия Н-Х/5121) | D29: Фаворит | E29: 41 | F29: 21
B30: А-24/1 | C30: Горошек овощной (богара) | E30: 39 | F30: 39
B31: Семена гороха овощного протравленные | C31: Фаворит 100 т.с.(партия Н-Х/5121) | D31: Фаворит | E31: 39 | F31: 39
B32: А-3 | C32: Горошек овощной (богара) | E32: 79 | F32: 158
B33: Семена гороха овощного протравленные | C33: Авола 100 тыс.с (лот D0021 15 K25-6011ST) | D33: Авола | E33: 79 | F33: 34
B34: Семена гороха овощного протравленные | C34: Авола 100 тыс.с (лот Kl1038104) | D34: Авола | E34: 79 | F34: 45
B35: Семена гороха овощного протравленные (кг) | C35: Преладо | E35: 79 | F35: 79
B36: А-38 | C36: Горошек овощной (богара) | E36: 38 | F36: 76
B37: Семена гороха овощного протравленные | C37: Авола 100 тыс.с (лот Kl1038104) | D37: Авола | E37: 38 | F37: 38
B38: Семена гороха овощного протравленные (кг) | C38: Преладо | E38: 38 | F38: 38
B39: А-4/1 | C39: Горошек овощной (богара) | E39: 111 | F39: 111
B40: Семена гороха овощного протравленные | C40: Тиара 100 т.с.(партия Н-Х/5116) | D40: Тиара | E40: 111 | F40: 62
...

Sheet Показатели по полям 2026
AR1: Уборка горошка в 2026 году на 06.07.2026
AR3: Сорт "Авола"
AR4: Валовый сбор, тонны | AU4: =GETPIVOTDATA(" Валовый сбор, т",$A$10) -> 1834.69
AR5: Площадь уборки, га | AU5: =AU4/AU6 -> 307.5
AR6: Урожайность вал.вес, т/га | AU6: =GETPIVOTDATA(" Урожайность вал.вес, т/га",$A$10) -> 5.9664715
AR7: Среднее значение финометра, % | AU7: =GETPIVOTDATA("Степень зрелости (финометр), %",$A$10) -> 57.437908
A10: Сорт/Поле/Дата уборки | B10: Степень зрелости (финометр), % | C10: Валовый сбор, т | D10: Урожайность вал.вес, т/га
A11: Авола | B11: 57.437908 | C11: 1834.69 | D11: 5.9664715
A12: А-105/1 | B12: 60.217391 | C12: 272.69 | D12: 5.0034862
A13: 46187 | B13: 57.833333 | C13: 68.82 | D13: 7.6466667
A14: 46188 | B14: 61.058824 | C14: 203.87 | D14: 4.4806593
A15: А-111/1 | B15: 55.5 | C15: 11.42 | D15: 5.71
A16: 46183 | B16: 55.5 | C16: 11.42 | D16: 5.71
A17: А-112/1 | B17: 63 | C17: 4.43 | D17: 4.43
A18: 46183 | B18: 63 | C18: 4.43 | D18: 4.43
A19: А-3 | B19: 49.657895 | C19: 447.05 | D19: 5.6588608
A20: 46177 | B20: 42 | C20: 6.12 | D20: 3.06
A21: 46180 | B21: 50.428571 | C21: 160.93 | D21: 5.3643333
A22: 46181 | B22: 49.55 | C22: 246.5 | D22: 6.0121951
A23: 46182 | B23: 49.333333 | C23: 33.5 | D23: 5.5833333
A24: А-38 | B24: 55.272727 | C24: 292.71 | D24: 7.7028947
A25: 46183 | B25: 55.272727 | C25: 292.71 | D25: 7.7028947
A26: А-5/1 | B26: 63.636364 | C26: 138.16 | D26: 5.3138462
A27: 46184 | B27: 63.636364 | C27: 138.16 | D27: 5.3138462
A28: А-76/3 | B28: 57.115385 | C28: 311.44 | D28: 7.5960976
A29: 46185 | B29: 48.75 | C29: 101.32 | D29: 6.7546667
A30: 46186 | B30: 60.833333 | C30: 210.12 | D30: 8.0815385
A31: А-76/5 | B31: 67.833333 | C31: 70.99 | D31: 5.0707143
A32: 46185 | B32: 67.833333 | C32: 70.99 | D32: 5.0707143
A33: А-83/2 | B33: 63.916667 | C33: 285.8 | D33: 5.4961538
A34: 46187 | B34: 63.888889 | C34: 214.95 | D34: 6.1414286
A35: 46188 | B35: 64 | C35: 70.85 | D35: 4.1676471
A36: Общий итог | B36: 57.437908 | C36: 1834.69 | D36: 5.9664715
AR37: Сорт "Женева"
AR38: Валовый сбор, тонны | AU38: =GETPIVOTDATA(" Валовый сбор, т",$F$45) -> 502.43
AR39: Площадь уборки, га | AU39: =AU38/AU40 -> 103.8
AR40: Урожайность вал.вес, т/га | AU40: =GETPIVOTDATA(" Урожайность вал.вес, т/га",$F$45) -> 4.8403661
AR41: Среднее значение финометра, % | AU41: =GETPIVOTDATA("Степень зрелости (финометр), %",$F$45) -> 54.696429
F45: Сорт/Поле/Дата уборки | G45: Степень зрелости (финометр), % | H45: Валовый сбор, т | I45: Урожайность вал.вес, т/га
F46: Женева | G46: 54.696429 | H46: 502.43 | I46: 4.8403661
...

Sheet Откл АВК и Отчета
A1: Культура | B1: Агролидер (полив) | J1: Культура | K1: Колос (полив) | P1: Культура | Q1: ГРК (богара)
F3: Значения | J3: Площадь уборки, га | P3: Площадь уборки, га
A4: Поле ОТЧЕТ | B4: Дата отчета | C4: № взвешивания | D4: № акта входного контроля | E4: Поле акт/ТТН | F4: Регистратор.Вес нетто | G4: Площадь уборки, га | J4: Поле ОТЧЕТ | K4: Дата отчета | L4: № акта входного контроля | M4: Поле акт | N4: Итог | P4: Поле ОТЧЕТ | Q4: Дата отчета | R4: Культура акт | S4: № акта входного контроля | T4: Поле акт | U4: Итог
A5: 12 Агролидер | B5: 46192 | C5: 460 | D5: 345 | E5: 12 Агролидер | F5: 13770 | G5: 3 | J5: 2.2 Колос | K5: 46198 | L5: 467 | M5: 2.2 Колос | N5: 3.5 | P5: А-104/1 | Q5: 46192 | R5: Горошек овощной 2026 (богара) | S5: 343 | T5: А-104/1 | U5: 1.4188888
C6: 462 | D6: 347 | E6: 12 Агролидер | F6: 4490 | G6: 1 | L6: 469 | M6: 2.2 Колос | N6: 3.4 | S6: 344 | T6: А-104/1 | U6: 1.9178387
B7: 46193 | C7: 467 | D7: 354 | E7: 12 Агролидер | F7: 4440 | G7: 1.2 | L7: 470 | M7: 2.2 Колос | N7: 3.4 | Q7: 46199 | R7: Горошек овощной 2026 (полив) | S7: 480 | T7: А-104/1 | U7: 1.2941513 | V7: Исправить культуру
C8: 468 | D8: 350 | E8: 12 Агролидер | F8: 12990 | G8: 3.6 | L8: 475 | M8: 2.2 Колос | N8: 3.4 | S8: 481 | T8: А-104/1 | U8: 1.334691 | V8: Исправить культуру
C9: 469 | D9: 351 | E9: 12 Агролидер | F9: 12870 | G9: 3.6 | L9: 479 | M9: 2.2 Колос | N9: 3.3 | S9: 483 | T9: А-104/1 | U9: 1.2380195 | V9: Исправить культуру
C10: 470 | D10: 352 | E10: 12 Агролидер | F10: 3980 | G10: 1.1 | L10: 723 | M10: 2.2 Колос | N10: 3 | S10: 486 | T10: А-104/1 | U10: 1.3596385 | V10: Исправить культуру
C11: 471 | D11: 353 | E11: 12 Агролидер | F11: 12720 | G11: 3.5 | L11: 724 | M11: 2.2 Колос | N11: 3.4 | S11: 487 | T11: А-104/1 | U11: 1.3970598 | V11: Исправить культуру
B12: 46195 | C12: 505 | D12: 386 | E12: 12 Агролидер | F12: 12870 | G12: 3.4 | L12: 721 | M12: 2.2 Колос | N12: 3.8 | P12: А-104/1 Итог | U12: 9.9602877 | V12: Исправить культуру и поле
C13: 508 | D13: 388 | E13: 12 Агролидер | F13: 13140 | G13: 3.5 | L13: 722 | M13: 2.2 Колос | N13: 2.8 | P13: А-105/1 | Q13: 46187 | R13: Горошек овощной 2026 (богара) | S13: 204 | T13: А-83/1 | U13: 1.1
C14: 509 | D14: 389 | E14: 12 Агролидер | F14: 13140 | G14: 3.5 | K14: 46199 | L14: 494 | M14: 2.2 Колос | N14: 7 | S14: 205 | T14: А-105/1 | U14: 1.8 | V14: Исправить поле
C15: 511 | D15: 390 | E15: 12 Агролидер | F15: 16020 | G15: 4.2 | L15: 495 | M15: 2.2 Колос | N15: 6.2 | S15: 206 | T15: А-105/1 | U15: 1.7
B16: 46196 | C16: 541 | D16: 418 | E16: 12 Агролидер | F16: 13480 | G16: 2.8 | L16: 496 | M16: 2.2 Колос | N16: 6.1 | S16: 207 | T16: А-105 | U16: 0.6
C17: 544 | D17: 421 | E17: 12 Агролидер | F17: 13390 | G17: 2.8 | L17: 526 | M17: 2.2 Колос | N17: 5.9 | S17: 208 | T17: А-105 | U17: 1.8 | V17: Исправить (уточнить) поле
C18: 547 | D18: 423 | E18: 12 Агролидер | F18: 16590 | G18: 3.4 | K18: 46200 | L18: 497 | M18: 2.2 Колос | N18: 4.2 | S18: 209 | T18: А-105/1 | U18: 2 | V18: Исправить (уточнить) поле
